[13/Aug/2024 17:14:40] ERROR [django.request:241] Internal Server Error: /dashboard/
Traceback (most recent call last):
  File "/usr/local/lib/python3.9/site-packages/django/core/files/storage/handler.py", line 35, in __getitem__
    return self._storages[alias]
KeyError: 'staticfiles'

During handling of the above exception, another exception occurred:

Traceback (most recent call last):
  File "/usr/local/lib/python3.9/site-packages/django/core/handlers/exception.py", line 55, in inner
    response = get_response(request)
  File "/usr/local/lib/python3.9/site-packages/django/core/handlers/base.py", line 197, in _get_response
    response = wrapped_callback(request, *callback_args, **callback_kwargs)
  File "/usr/local/lib/python3.9/site-packages/django/contrib/auth/decorators.py", line 23, in _wrapper_view
    return view_func(request, *args, **kwargs)
  File "/app/backend/dashboard/views.py", line 87, in dashboard
    return render(request, "dashboard/dashboard.html", context=context)
  File "/usr/local/lib/python3.9/site-packages/django/shortcuts.py", line 24, in render
    content = loader.render_to_string(template_name, context, request, using=using)
  File "/usr/local/lib/python3.9/site-packages/django/template/loader.py", line 62, in render_to_string
    return template.render(context, request)
  File "/usr/local/lib/python3.9/site-packages/django/template/backends/django.py", line 61, in render
    return self.template.render(context)
  File "/usr/local/lib/python3.9/site-packages/django/template/base.py", line 175, in render
    return self._render(context)
  File "/usr/local/lib/python3.9/site-packages/django/template/base.py", line 167, in _render
    return self.nodelist.render(context)
  File "/usr/local/lib/python3.9/site-packages/django/template/base.py", line 1005, in render
    return SafeString("".join([node.render_annotated(context) for node in self]))
  File "/usr/local/lib/python3.9/site-packages/django/template/base.py", line 1005, in <listcomp>
    return SafeString("".join([node.render_annotated(context) for node in self]))
  File "/usr/local/lib/python3.9/site-packages/django/template/base.py", line 966, in render_annotated
    return self.render(context)
  File "/usr/local/lib/python3.9/site-packages/django/templatetags/static.py", line 116, in render
    url = self.url(context)
  File "/usr/local/lib/python3.9/site-packages/django/templatetags/static.py", line 113, in url
    return self.handle_simple(path)
  File "/usr/local/lib/python3.9/site-packages/django/templatetags/static.py", line 129, in handle_simple
    return staticfiles_storage.url(path)
  File "/usr/local/lib/python3.9/site-packages/django/utils/functional.py", line 266, in inner
    self._setup()
  File "/usr/local/lib/python3.9/site-packages/django/contrib/staticfiles/storage.py", line 537, in _setup
    self._wrapped = storages[STATICFILES_STORAGE_ALIAS]
  File "/usr/local/lib/python3.9/site-packages/django/core/files/storage/handler.py", line 43, in __getitem__
    storage = self.create_storage(params)
  File "/usr/local/lib/python3.9/site-packages/django/core/files/storage/handler.py", line 55, in create_storage
    return storage_cls(**options)
  File "/usr/local/lib/python3.9/site-packages/django/contrib/staticfiles/storage.py", line 29, in __init__
    check_settings(base_url)
  File "/usr/local/lib/python3.9/site-packages/django/contrib/staticfiles/utils.py", line 49, in check_settings
    raise ImproperlyConfigured(
django.core.exceptions.ImproperlyConfigured: You're using the staticfiles app without having set the required STATIC_URL setting.
