[24/Jun/2024 19:04:29] ERROR [django.request:241] Internal Server Error: /auth/login/
Traceback (most recent call last):
  File "C:\Users\aksha\code\merchstore\backend\login\backend.py", line 19, in authenticate
    user = User.objects.get(email=user_info['email'])
  File "C:\Users\aksha\code\merchstore\venv\lib\site-packages\django\db\models\manager.py", line 87, in manager_method
    return getattr(self.get_queryset(), name)(*args, **kwargs)
  File "C:\Users\aksha\code\merchstore\venv\lib\site-packages\django\db\models\query.py", line 637, in get
    raise self.model.DoesNotExist(
login.models.CustomUser.DoesNotExist: CustomUser matching query does not exist.

During handling of the above exception, another exception occurred:

Traceback (most recent call last):
  File "C:\Users\aksha\code\merchstore\venv\lib\site-packages\django\db\backends\utils.py", line 89, in _execute
    return self.cursor.execute(sql, params)
psycopg2.errors.StringDataRightTruncation: value too long for type character varying(2)


The above exception was the direct cause of the following exception:

Traceback (most recent call last):
  File "C:\Users\aksha\code\merchstore\venv\lib\site-packages\django\core\handlers\exception.py", line 55, in inner
    response = get_response(request)
  File "C:\Users\aksha\code\merchstore\venv\lib\site-packages\django\core\handlers\base.py", line 197, in _get_response
    response = wrapped_callback(request, *callback_args, **callback_kwargs)
  File "C:\Users\aksha\code\merchstore\venv\lib\site-packages\django\views\decorators\csrf.py", line 56, in wrapper_view
    return view_func(*args, **kwargs)
  File "C:\Users\aksha\code\merchstore\venv\lib\site-packages\django\views\generic\base.py", line 104, in view
    return self.dispatch(request, *args, **kwargs)
  File "C:\Users\aksha\code\merchstore\venv\lib\site-packages\rest_framework\views.py", line 509, in dispatch
    response = self.handle_exception(exc)
  File "C:\Users\aksha\code\merchstore\venv\lib\site-packages\rest_framework\views.py", line 469, in handle_exception
    self.raise_uncaught_exception(exc)
  File "C:\Users\aksha\code\merchstore\venv\lib\site-packages\rest_framework\views.py", line 480, in raise_uncaught_exception
    raise exc
  File "C:\Users\aksha\code\merchstore\venv\lib\site-packages\rest_framework\views.py", line 506, in dispatch
    response = handler(request, *args, **kwargs)
  File "C:\Users\aksha\code\merchstore\backend\login\views.py", line 23, in post
    user = authenticate(request, sso_token=sso_token)
  File "C:\Users\aksha\code\merchstore\venv\lib\site-packages\django\views\decorators\debug.py", line 42, in sensitive_variables_wrapper
    return func(*func_args, **func_kwargs)
  File "C:\Users\aksha\code\merchstore\venv\lib\site-packages\django\contrib\auth\__init__.py", line 77, in authenticate
    user = backend.authenticate(request, **credentials)
  File "C:\Users\aksha\code\merchstore\backend\login\backend.py", line 21, in authenticate
    user = User.objects.create(
  File "C:\Users\aksha\code\merchstore\venv\lib\site-packages\django\db\models\manager.py", line 87, in manager_method
    return getattr(self.get_queryset(), name)(*args, **kwargs)
  File "C:\Users\aksha\code\merchstore\venv\lib\site-packages\django\db\models\query.py", line 658, in create
    obj.save(force_insert=True, using=self.db)
  File "C:\Users\aksha\code\merchstore\venv\lib\site-packages\django\contrib\auth\base_user.py", line 76, in save
    super().save(*args, **kwargs)
  File "C:\Users\aksha\code\merchstore\venv\lib\site-packages\django\db\models\base.py", line 814, in save
    self.save_base(
  File "C:\Users\aksha\code\merchstore\venv\lib\site-packages\django\db\models\base.py", line 877, in save_base
    updated = self._save_table(
  File "C:\Users\aksha\code\merchstore\venv\lib\site-packages\django\db\models\base.py", line 1020, in _save_table
    results = self._do_insert(
  File "C:\Users\aksha\code\merchstore\venv\lib\site-packages\django\db\models\base.py", line 1061, in _do_insert
    return manager._insert(
  File "C:\Users\aksha\code\merchstore\venv\lib\site-packages\django\db\models\manager.py", line 87, in manager_method
    return getattr(self.get_queryset(), name)(*args, **kwargs)
  File "C:\Users\aksha\code\merchstore\venv\lib\site-packages\django\db\models\query.py", line 1805, in _insert
    return query.get_compiler(using=using).execute_sql(returning_fields)
  File "C:\Users\aksha\code\merchstore\venv\lib\site-packages\django\db\models\sql\compiler.py", line 1822, in execute_sql
    cursor.execute(sql, params)
  File "C:\Users\aksha\code\merchstore\venv\lib\site-packages\django\db\backends\utils.py", line 102, in execute
    return super().execute(sql, params)
  File "C:\Users\aksha\code\merchstore\venv\lib\site-packages\django\db\backends\utils.py", line 67, in execute
    return self._execute_with_wrappers(
  File "C:\Users\aksha\code\merchstore\venv\lib\site-packages\django\db\backends\utils.py", line 80, in _execute_with_wrappers
    return executor(sql, params, many, context)
  File "C:\Users\aksha\code\merchstore\venv\lib\site-packages\django\db\backends\utils.py", line 89, in _execute
    return self.cursor.execute(sql, params)
  File "C:\Users\aksha\code\merchstore\venv\lib\site-packages\django\db\utils.py", line 91, in __exit__
    raise dj_exc_value.with_traceback(traceback) from exc_value
  File "C:\Users\aksha\code\merchstore\venv\lib\site-packages\django\db\backends\utils.py", line 89, in _execute
    return self.cursor.execute(sql, params)
django.db.utils.DataError: value too long for type character varying(2)

[24/Jun/2024 19:04:29] ERROR [django.server:212] "POST /auth/login/ HTTP/1.1" 500 214226
[24/Jun/2024 19:06:04] ERROR [django.request:241] Internal Server Error: /auth/login/
Traceback (most recent call last):
  File "C:\Users\aksha\code\merchstore\backend\login\backend.py", line 19, in authenticate
    user = User.objects.get(email=user_info['email'])
  File "C:\Users\aksha\code\merchstore\venv\lib\site-packages\django\db\models\manager.py", line 87, in manager_method
    return getattr(self.get_queryset(), name)(*args, **kwargs)
  File "C:\Users\aksha\code\merchstore\venv\lib\site-packages\django\db\models\query.py", line 637, in get
    raise self.model.DoesNotExist(
login.models.CustomUser.DoesNotExist: CustomUser matching query does not exist.

During handling of the above exception, another exception occurred:

Traceback (most recent call last):
  File "C:\Users\aksha\code\merchstore\venv\lib\site-packages\django\db\backends\utils.py", line 89, in _execute
    return self.cursor.execute(sql, params)
psycopg2.errors.StringDataRightTruncation: value too long for type character varying(2)


The above exception was the direct cause of the following exception:

Traceback (most recent call last):
  File "C:\Users\aksha\code\merchstore\venv\lib\site-packages\django\core\handlers\exception.py", line 55, in inner
    response = get_response(request)
  File "C:\Users\aksha\code\merchstore\venv\lib\site-packages\django\core\handlers\base.py", line 197, in _get_response
    response = wrapped_callback(request, *callback_args, **callback_kwargs)
  File "C:\Users\aksha\code\merchstore\venv\lib\site-packages\django\views\decorators\csrf.py", line 56, in wrapper_view
    return view_func(*args, **kwargs)
  File "C:\Users\aksha\code\merchstore\venv\lib\site-packages\django\views\generic\base.py", line 104, in view
    return self.dispatch(request, *args, **kwargs)
  File "C:\Users\aksha\code\merchstore\venv\lib\site-packages\rest_framework\views.py", line 509, in dispatch
    response = self.handle_exception(exc)
  File "C:\Users\aksha\code\merchstore\venv\lib\site-packages\rest_framework\views.py", line 469, in handle_exception
    self.raise_uncaught_exception(exc)
  File "C:\Users\aksha\code\merchstore\venv\lib\site-packages\rest_framework\views.py", line 480, in raise_uncaught_exception
    raise exc
  File "C:\Users\aksha\code\merchstore\venv\lib\site-packages\rest_framework\views.py", line 506, in dispatch
    response = handler(request, *args, **kwargs)
  File "C:\Users\aksha\code\merchstore\backend\login\views.py", line 23, in post
    user = authenticate(request, sso_token=sso_token)
  File "C:\Users\aksha\code\merchstore\venv\lib\site-packages\django\views\decorators\debug.py", line 42, in sensitive_variables_wrapper
    return func(*func_args, **func_kwargs)
  File "C:\Users\aksha\code\merchstore\venv\lib\site-packages\django\contrib\auth\__init__.py", line 77, in authenticate
    user = backend.authenticate(request, **credentials)
  File "C:\Users\aksha\code\merchstore\backend\login\backend.py", line 21, in authenticate
    user = User.objects.create(
  File "C:\Users\aksha\code\merchstore\venv\lib\site-packages\django\db\models\manager.py", line 87, in manager_method
    return getattr(self.get_queryset(), name)(*args, **kwargs)
  File "C:\Users\aksha\code\merchstore\venv\lib\site-packages\django\db\models\query.py", line 658, in create
    obj.save(force_insert=True, using=self.db)
  File "C:\Users\aksha\code\merchstore\venv\lib\site-packages\django\contrib\auth\base_user.py", line 76, in save
    super().save(*args, **kwargs)
  File "C:\Users\aksha\code\merchstore\venv\lib\site-packages\django\db\models\base.py", line 814, in save
    self.save_base(
  File "C:\Users\aksha\code\merchstore\venv\lib\site-packages\django\db\models\base.py", line 877, in save_base
    updated = self._save_table(
  File "C:\Users\aksha\code\merchstore\venv\lib\site-packages\django\db\models\base.py", line 1020, in _save_table
    results = self._do_insert(
  File "C:\Users\aksha\code\merchstore\venv\lib\site-packages\django\db\models\base.py", line 1061, in _do_insert
    return manager._insert(
  File "C:\Users\aksha\code\merchstore\venv\lib\site-packages\django\db\models\manager.py", line 87, in manager_method
    return getattr(self.get_queryset(), name)(*args, **kwargs)
  File "C:\Users\aksha\code\merchstore\venv\lib\site-packages\django\db\models\query.py", line 1805, in _insert
    return query.get_compiler(using=using).execute_sql(returning_fields)
  File "C:\Users\aksha\code\merchstore\venv\lib\site-packages\django\db\models\sql\compiler.py", line 1822, in execute_sql
    cursor.execute(sql, params)
  File "C:\Users\aksha\code\merchstore\venv\lib\site-packages\django\db\backends\utils.py", line 102, in execute
    return super().execute(sql, params)
  File "C:\Users\aksha\code\merchstore\venv\lib\site-packages\django\db\backends\utils.py", line 67, in execute
    return self._execute_with_wrappers(
  File "C:\Users\aksha\code\merchstore\venv\lib\site-packages\django\db\backends\utils.py", line 80, in _execute_with_wrappers
    return executor(sql, params, many, context)
  File "C:\Users\aksha\code\merchstore\venv\lib\site-packages\django\db\backends\utils.py", line 89, in _execute
    return self.cursor.execute(sql, params)
  File "C:\Users\aksha\code\merchstore\venv\lib\site-packages\django\db\utils.py", line 91, in __exit__
    raise dj_exc_value.with_traceback(traceback) from exc_value
  File "C:\Users\aksha\code\merchstore\venv\lib\site-packages\django\db\backends\utils.py", line 89, in _execute
    return self.cursor.execute(sql, params)
django.db.utils.DataError: value too long for type character varying(2)

[24/Jun/2024 19:06:05] ERROR [django.server:212] "POST /auth/login/ HTTP/1.1" 500 214226
[24/Jun/2024 19:06:11] ERROR [django.request:241] Internal Server Error: /auth/login/
Traceback (most recent call last):
  File "C:\Users\aksha\code\merchstore\backend\login\backend.py", line 19, in authenticate
    user = User.objects.get(email=user_info['email'])
  File "C:\Users\aksha\code\merchstore\venv\lib\site-packages\django\db\models\manager.py", line 87, in manager_method
    return getattr(self.get_queryset(), name)(*args, **kwargs)
  File "C:\Users\aksha\code\merchstore\venv\lib\site-packages\django\db\models\query.py", line 637, in get
    raise self.model.DoesNotExist(
login.models.CustomUser.DoesNotExist: CustomUser matching query does not exist.

During handling of the above exception, another exception occurred:

Traceback (most recent call last):
  File "C:\Users\aksha\code\merchstore\venv\lib\site-packages\django\db\backends\utils.py", line 89, in _execute
    return self.cursor.execute(sql, params)
psycopg2.errors.StringDataRightTruncation: value too long for type character varying(2)


The above exception was the direct cause of the following exception:

Traceback (most recent call last):
  File "C:\Users\aksha\code\merchstore\venv\lib\site-packages\django\core\handlers\exception.py", line 55, in inner
    response = get_response(request)
  File "C:\Users\aksha\code\merchstore\venv\lib\site-packages\django\core\handlers\base.py", line 197, in _get_response
    response = wrapped_callback(request, *callback_args, **callback_kwargs)
  File "C:\Users\aksha\code\merchstore\venv\lib\site-packages\django\views\decorators\csrf.py", line 56, in wrapper_view
    return view_func(*args, **kwargs)
  File "C:\Users\aksha\code\merchstore\venv\lib\site-packages\django\views\generic\base.py", line 104, in view
    return self.dispatch(request, *args, **kwargs)
  File "C:\Users\aksha\code\merchstore\venv\lib\site-packages\rest_framework\views.py", line 509, in dispatch
    response = self.handle_exception(exc)
  File "C:\Users\aksha\code\merchstore\venv\lib\site-packages\rest_framework\views.py", line 469, in handle_exception
    self.raise_uncaught_exception(exc)
  File "C:\Users\aksha\code\merchstore\venv\lib\site-packages\rest_framework\views.py", line 480, in raise_uncaught_exception
    raise exc
  File "C:\Users\aksha\code\merchstore\venv\lib\site-packages\rest_framework\views.py", line 506, in dispatch
    response = handler(request, *args, **kwargs)
  File "C:\Users\aksha\code\merchstore\backend\login\views.py", line 23, in post
    user = authenticate(request, sso_token=sso_token)
  File "C:\Users\aksha\code\merchstore\venv\lib\site-packages\django\views\decorators\debug.py", line 42, in sensitive_variables_wrapper
    return func(*func_args, **func_kwargs)
  File "C:\Users\aksha\code\merchstore\venv\lib\site-packages\django\contrib\auth\__init__.py", line 77, in authenticate
    user = backend.authenticate(request, **credentials)
  File "C:\Users\aksha\code\merchstore\backend\login\backend.py", line 21, in authenticate
    user = User.objects.create(
  File "C:\Users\aksha\code\merchstore\venv\lib\site-packages\django\db\models\manager.py", line 87, in manager_method
    return getattr(self.get_queryset(), name)(*args, **kwargs)
  File "C:\Users\aksha\code\merchstore\venv\lib\site-packages\django\db\models\query.py", line 658, in create
    obj.save(force_insert=True, using=self.db)
  File "C:\Users\aksha\code\merchstore\venv\lib\site-packages\django\contrib\auth\base_user.py", line 76, in save
    super().save(*args, **kwargs)
  File "C:\Users\aksha\code\merchstore\venv\lib\site-packages\django\db\models\base.py", line 814, in save
    self.save_base(
  File "C:\Users\aksha\code\merchstore\venv\lib\site-packages\django\db\models\base.py", line 877, in save_base
    updated = self._save_table(
  File "C:\Users\aksha\code\merchstore\venv\lib\site-packages\django\db\models\base.py", line 1020, in _save_table
    results = self._do_insert(
  File "C:\Users\aksha\code\merchstore\venv\lib\site-packages\django\db\models\base.py", line 1061, in _do_insert
    return manager._insert(
  File "C:\Users\aksha\code\merchstore\venv\lib\site-packages\django\db\models\manager.py", line 87, in manager_method
    return getattr(self.get_queryset(), name)(*args, **kwargs)
  File "C:\Users\aksha\code\merchstore\venv\lib\site-packages\django\db\models\query.py", line 1805, in _insert
    return query.get_compiler(using=using).execute_sql(returning_fields)
  File "C:\Users\aksha\code\merchstore\venv\lib\site-packages\django\db\models\sql\compiler.py", line 1822, in execute_sql
    cursor.execute(sql, params)
  File "C:\Users\aksha\code\merchstore\venv\lib\site-packages\django\db\backends\utils.py", line 102, in execute
    return super().execute(sql, params)
  File "C:\Users\aksha\code\merchstore\venv\lib\site-packages\django\db\backends\utils.py", line 67, in execute
    return self._execute_with_wrappers(
  File "C:\Users\aksha\code\merchstore\venv\lib\site-packages\django\db\backends\utils.py", line 80, in _execute_with_wrappers
    return executor(sql, params, many, context)
  File "C:\Users\aksha\code\merchstore\venv\lib\site-packages\django\db\backends\utils.py", line 89, in _execute
    return self.cursor.execute(sql, params)
  File "C:\Users\aksha\code\merchstore\venv\lib\site-packages\django\db\utils.py", line 91, in __exit__
    raise dj_exc_value.with_traceback(traceback) from exc_value
  File "C:\Users\aksha\code\merchstore\venv\lib\site-packages\django\db\backends\utils.py", line 89, in _execute
    return self.cursor.execute(sql, params)
django.db.utils.DataError: value too long for type character varying(2)

[24/Jun/2024 19:06:11] ERROR [django.server:212] "POST /auth/login/ HTTP/1.1" 500 214226
[26/Jun/2024 15:15:02] ERROR [django.request:241] Internal Server Error: /auth/login
Traceback (most recent call last):
  File "C:\Users\Sakshham\AppData\Local\Programs\Python\Python312\Lib\site-packages\django\core\handlers\exception.py", line 55, in inner
    response = get_response(request)
               ^^^^^^^^^^^^^^^^^^^^^
  File "C:\Users\Sakshham\AppData\Local\Programs\Python\Python312\Lib\site-packages\django\utils\deprecation.py", line 136, in __call__
    response = self.process_response(request, response)
               ^^^^^^^^^^^^^^^^^^^^^^^^^^^^^^^^^^^^^^^^
  File "C:\Users\Sakshham\AppData\Local\Programs\Python\Python312\Lib\site-packages\django\middleware\common.py", line 108, in process_response
    return self.response_redirect_class(self.get_full_path_with_slash(request))
                                        ^^^^^^^^^^^^^^^^^^^^^^^^^^^^^^^^^^^^^^
  File "C:\Users\Sakshham\AppData\Local\Programs\Python\Python312\Lib\site-packages\django\middleware\common.py", line 87, in get_full_path_with_slash
    raise RuntimeError(
RuntimeError: You called this URL via POST, but the URL doesn't end in a slash and you have APPEND_SLASH set. Django can't redirect to the slash URL while maintaining POST data. Change your form to point to localhost:8000/auth/login/ (note the trailing slash), or set APPEND_SLASH=False in your Django settings.
[26/Jun/2024 15:15:02] ERROR [django.server:212] "POST /auth/login HTTP/1.1" 500 73767
[26/Jun/2024 15:17:42] ERROR [django.request:241] Internal Server Error: /auth/login
Traceback (most recent call last):
  File "C:\Users\Sakshham\AppData\Local\Programs\Python\Python312\Lib\site-packages\django\core\handlers\exception.py", line 55, in inner
    response = get_response(request)
               ^^^^^^^^^^^^^^^^^^^^^
  File "C:\Users\Sakshham\AppData\Local\Programs\Python\Python312\Lib\site-packages\django\utils\deprecation.py", line 136, in __call__
    response = self.process_response(request, response)
               ^^^^^^^^^^^^^^^^^^^^^^^^^^^^^^^^^^^^^^^^
  File "C:\Users\Sakshham\AppData\Local\Programs\Python\Python312\Lib\site-packages\django\middleware\common.py", line 108, in process_response
    return self.response_redirect_class(self.get_full_path_with_slash(request))
                                        ^^^^^^^^^^^^^^^^^^^^^^^^^^^^^^^^^^^^^^
  File "C:\Users\Sakshham\AppData\Local\Programs\Python\Python312\Lib\site-packages\django\middleware\common.py", line 87, in get_full_path_with_slash
    raise RuntimeError(
RuntimeError: You called this URL via POST, but the URL doesn't end in a slash and you have APPEND_SLASH set. Django can't redirect to the slash URL while maintaining POST data. Change your form to point to localhost:8000/auth/login/ (note the trailing slash), or set APPEND_SLASH=False in your Django settings.
[26/Jun/2024 15:17:42] ERROR [django.server:212] "POST /auth/login HTTP/1.1" 500 77081
[26/Jun/2024 15:34:08] ERROR [django.request:241] Internal Server Error: /product/all/
Traceback (most recent call last):
  File "C:\Users\Sakshham\AppData\Local\Programs\Python\Python312\Lib\site-packages\django\db\backends\utils.py", line 89, in _execute
    return self.cursor.execute(sql, params)
           ^^^^^^^^^^^^^^^^^^^^^^^^^^^^^^^^
psycopg2.errors.InvalidTextRepresentation: malformed array literal: "MB"
LINE 1: ...WHERE ("products_product"."for_user_positions" @> 'MB'::varc...
                                                             ^
DETAIL:  Array value must start with "{" or dimension information.


The above exception was the direct cause of the following exception:

Traceback (most recent call last):
  File "C:\Users\Sakshham\AppData\Local\Programs\Python\Python312\Lib\site-packages\django\core\handlers\exception.py", line 55, in inner
    response = get_response(request)
               ^^^^^^^^^^^^^^^^^^^^^
  File "C:\Users\Sakshham\AppData\Local\Programs\Python\Python312\Lib\site-packages\django\core\handlers\base.py", line 197, in _get_response
    response = wrapped_callback(request, *callback_args, **callback_kwargs)
               ^^^^^^^^^^^^^^^^^^^^^^^^^^^^^^^^^^^^^^^^^^^^^^^^^^^^^^^^^^^^
  File "C:\Users\Sakshham\AppData\Local\Programs\Python\Python312\Lib\site-packages\django\views\decorators\csrf.py", line 56, in wrapper_view
    return view_func(*args, **kwargs)
           ^^^^^^^^^^^^^^^^^^^^^^^^^^
  File "C:\Users\Sakshham\AppData\Local\Programs\Python\Python312\Lib\site-packages\django\views\generic\base.py", line 104, in view
    return self.dispatch(request, *args, **kwargs)
           ^^^^^^^^^^^^^^^^^^^^^^^^^^^^^^^^^^^^^^^
  File "C:\Users\Sakshham\AppData\Local\Programs\Python\Python312\Lib\site-packages\rest_framework\views.py", line 509, in dispatch
    response = self.handle_exception(exc)
               ^^^^^^^^^^^^^^^^^^^^^^^^^^
  File "C:\Users\Sakshham\AppData\Local\Programs\Python\Python312\Lib\site-packages\rest_framework\views.py", line 469, in handle_exception
    self.raise_uncaught_exception(exc)
  File "C:\Users\Sakshham\AppData\Local\Programs\Python\Python312\Lib\site-packages\rest_framework\views.py", line 480, in raise_uncaught_exception
    raise exc
  File "C:\Users\Sakshham\AppData\Local\Programs\Python\Python312\Lib\site-packages\rest_framework\views.py", line 506, in dispatch
    response = handler(request, *args, **kwargs)
               ^^^^^^^^^^^^^^^^^^^^^^^^^^^^^^^^^
  File "D:\ALL CODES\Professional work\merch_store_backend\backend\products\views.py", line 22, in get
    return Response(serializer.data, status=status.HTTP_200_OK)
                    ^^^^^^^^^^^^^^^
  File "C:\Users\Sakshham\AppData\Local\Programs\Python\Python312\Lib\site-packages\rest_framework\serializers.py", line 795, in data
    ret = super().data
          ^^^^^^^^^^^^
  File "C:\Users\Sakshham\AppData\Local\Programs\Python\Python312\Lib\site-packages\rest_framework\serializers.py", line 249, in data
    self._data = self.to_representation(self.instance)
                 ^^^^^^^^^^^^^^^^^^^^^^^^^^^^^^^^^^^^^
  File "C:\Users\Sakshham\AppData\Local\Programs\Python\Python312\Lib\site-packages\rest_framework\serializers.py", line 713, in to_representation
    return [
           ^
  File "C:\Users\Sakshham\AppData\Local\Programs\Python\Python312\Lib\site-packages\django\db\models\query.py", line 398, in __iter__
    self._fetch_all()
  File "C:\Users\Sakshham\AppData\Local\Programs\Python\Python312\Lib\site-packages\django\db\models\query.py", line 1881, in _fetch_all
    self._result_cache = list(self._iterable_class(self))
                         ^^^^^^^^^^^^^^^^^^^^^^^^^^^^^^^^
  File "C:\Users\Sakshham\AppData\Local\Programs\Python\Python312\Lib\site-packages\django\db\models\query.py", line 91, in __iter__
    results = compiler.execute_sql(
              ^^^^^^^^^^^^^^^^^^^^^
  File "C:\Users\Sakshham\AppData\Local\Programs\Python\Python312\Lib\site-packages\django\db\models\sql\compiler.py", line 1562, in execute_sql
    cursor.execute(sql, params)
  File "C:\Users\Sakshham\AppData\Local\Programs\Python\Python312\Lib\site-packages\django\db\backends\utils.py", line 102, in execute
    return super().execute(sql, params)
           ^^^^^^^^^^^^^^^^^^^^^^^^^^^^
  File "C:\Users\Sakshham\AppData\Local\Programs\Python\Python312\Lib\site-packages\django\db\backends\utils.py", line 67, in execute
    return self._execute_with_wrappers(
           ^^^^^^^^^^^^^^^^^^^^^^^^^^^^
  File "C:\Users\Sakshham\AppData\Local\Programs\Python\Python312\Lib\site-packages\django\db\backends\utils.py", line 80, in _execute_with_wrappers
    return executor(sql, params, many, context)
           ^^^^^^^^^^^^^^^^^^^^^^^^^^^^^^^^^^^^
  File "C:\Users\Sakshham\AppData\Local\Programs\Python\Python312\Lib\site-packages\django\db\backends\utils.py", line 84, in _execute
    with self.db.wrap_database_errors:
  File "C:\Users\Sakshham\AppData\Local\Programs\Python\Python312\Lib\site-packages\django\db\utils.py", line 91, in __exit__
    raise dj_exc_value.with_traceback(traceback) from exc_value
  File "C:\Users\Sakshham\AppData\Local\Programs\Python\Python312\Lib\site-packages\django\db\backends\utils.py", line 89, in _execute
    return self.cursor.execute(sql, params)
           ^^^^^^^^^^^^^^^^^^^^^^^^^^^^^^^^
django.db.utils.DataError: malformed array literal: "MB"
LINE 1: ...WHERE ("products_product"."for_user_positions" @> 'MB'::varc...
                                                             ^
DETAIL:  Array value must start with "{" or dimension information.

[26/Jun/2024 15:34:08] ERROR [django.server:212] "GET /product/all/ HTTP/1.1" 500 171925
[26/Jun/2024 15:37:40] ERROR [django.request:241] Internal Server Error: /product/all/
Traceback (most recent call last):
  File "C:\Users\Sakshham\AppData\Local\Programs\Python\Python312\Lib\site-packages\django\db\backends\utils.py", line 89, in _execute
    return self.cursor.execute(sql, params)
           ^^^^^^^^^^^^^^^^^^^^^^^^^^^^^^^^
psycopg2.errors.InvalidTextRepresentation: malformed array literal: "MB"
LINE 1: ...WHERE ("products_product"."for_user_positions" @> 'MB'::varc...
                                                             ^
DETAIL:  Array value must start with "{" or dimension information.


The above exception was the direct cause of the following exception:

Traceback (most recent call last):
  File "C:\Users\Sakshham\AppData\Local\Programs\Python\Python312\Lib\site-packages\django\core\handlers\exception.py", line 55, in inner
    response = get_response(request)
               ^^^^^^^^^^^^^^^^^^^^^
  File "C:\Users\Sakshham\AppData\Local\Programs\Python\Python312\Lib\site-packages\django\core\handlers\base.py", line 197, in _get_response
    response = wrapped_callback(request, *callback_args, **callback_kwargs)
               ^^^^^^^^^^^^^^^^^^^^^^^^^^^^^^^^^^^^^^^^^^^^^^^^^^^^^^^^^^^^
  File "C:\Users\Sakshham\AppData\Local\Programs\Python\Python312\Lib\site-packages\django\views\decorators\csrf.py", line 56, in wrapper_view
    return view_func(*args, **kwargs)
           ^^^^^^^^^^^^^^^^^^^^^^^^^^
  File "C:\Users\Sakshham\AppData\Local\Programs\Python\Python312\Lib\site-packages\django\views\generic\base.py", line 104, in view
    return self.dispatch(request, *args, **kwargs)
           ^^^^^^^^^^^^^^^^^^^^^^^^^^^^^^^^^^^^^^^
  File "C:\Users\Sakshham\AppData\Local\Programs\Python\Python312\Lib\site-packages\rest_framework\views.py", line 509, in dispatch
    response = self.handle_exception(exc)
               ^^^^^^^^^^^^^^^^^^^^^^^^^^
  File "C:\Users\Sakshham\AppData\Local\Programs\Python\Python312\Lib\site-packages\rest_framework\views.py", line 469, in handle_exception
    self.raise_uncaught_exception(exc)
  File "C:\Users\Sakshham\AppData\Local\Programs\Python\Python312\Lib\site-packages\rest_framework\views.py", line 480, in raise_uncaught_exception
    raise exc
  File "C:\Users\Sakshham\AppData\Local\Programs\Python\Python312\Lib\site-packages\rest_framework\views.py", line 506, in dispatch
    response = handler(request, *args, **kwargs)
               ^^^^^^^^^^^^^^^^^^^^^^^^^^^^^^^^^
  File "D:\ALL CODES\Professional work\merch_store_backend\backend\products\views.py", line 22, in get
    return Response(serializer.data, status=status.HTTP_200_OK)
                    ^^^^^^^^^^^^^^^
  File "C:\Users\Sakshham\AppData\Local\Programs\Python\Python312\Lib\site-packages\rest_framework\serializers.py", line 795, in data
    ret = super().data
          ^^^^^^^^^^^^
  File "C:\Users\Sakshham\AppData\Local\Programs\Python\Python312\Lib\site-packages\rest_framework\serializers.py", line 249, in data
    self._data = self.to_representation(self.instance)
                 ^^^^^^^^^^^^^^^^^^^^^^^^^^^^^^^^^^^^^
  File "C:\Users\Sakshham\AppData\Local\Programs\Python\Python312\Lib\site-packages\rest_framework\serializers.py", line 713, in to_representation
    return [
           ^
  File "C:\Users\Sakshham\AppData\Local\Programs\Python\Python312\Lib\site-packages\django\db\models\query.py", line 398, in __iter__
    self._fetch_all()
  File "C:\Users\Sakshham\AppData\Local\Programs\Python\Python312\Lib\site-packages\django\db\models\query.py", line 1881, in _fetch_all
    self._result_cache = list(self._iterable_class(self))
                         ^^^^^^^^^^^^^^^^^^^^^^^^^^^^^^^^
  File "C:\Users\Sakshham\AppData\Local\Programs\Python\Python312\Lib\site-packages\django\db\models\query.py", line 91, in __iter__
    results = compiler.execute_sql(
              ^^^^^^^^^^^^^^^^^^^^^
  File "C:\Users\Sakshham\AppData\Local\Programs\Python\Python312\Lib\site-packages\django\db\models\sql\compiler.py", line 1562, in execute_sql
    cursor.execute(sql, params)
  File "C:\Users\Sakshham\AppData\Local\Programs\Python\Python312\Lib\site-packages\django\db\backends\utils.py", line 102, in execute
    return super().execute(sql, params)
           ^^^^^^^^^^^^^^^^^^^^^^^^^^^^
  File "C:\Users\Sakshham\AppData\Local\Programs\Python\Python312\Lib\site-packages\django\db\backends\utils.py", line 67, in execute
    return self._execute_with_wrappers(
           ^^^^^^^^^^^^^^^^^^^^^^^^^^^^
  File "C:\Users\Sakshham\AppData\Local\Programs\Python\Python312\Lib\site-packages\django\db\backends\utils.py", line 80, in _execute_with_wrappers
    return executor(sql, params, many, context)
           ^^^^^^^^^^^^^^^^^^^^^^^^^^^^^^^^^^^^
  File "C:\Users\Sakshham\AppData\Local\Programs\Python\Python312\Lib\site-packages\django\db\backends\utils.py", line 84, in _execute
    with self.db.wrap_database_errors:
  File "C:\Users\Sakshham\AppData\Local\Programs\Python\Python312\Lib\site-packages\django\db\utils.py", line 91, in __exit__
    raise dj_exc_value.with_traceback(traceback) from exc_value
  File "C:\Users\Sakshham\AppData\Local\Programs\Python\Python312\Lib\site-packages\django\db\backends\utils.py", line 89, in _execute
    return self.cursor.execute(sql, params)
           ^^^^^^^^^^^^^^^^^^^^^^^^^^^^^^^^
django.db.utils.DataError: malformed array literal: "MB"
LINE 1: ...WHERE ("products_product"."for_user_positions" @> 'MB'::varc...
                                                             ^
DETAIL:  Array value must start with "{" or dimension information.

[26/Jun/2024 15:37:40] ERROR [django.server:212] "GET /product/all/ HTTP/1.1" 500 171923
[26/Jun/2024 15:37:44] ERROR [django.request:241] Internal Server Error: /product/all/
Traceback (most recent call last):
  File "C:\Users\Sakshham\AppData\Local\Programs\Python\Python312\Lib\site-packages\django\db\backends\utils.py", line 89, in _execute
    return self.cursor.execute(sql, params)
           ^^^^^^^^^^^^^^^^^^^^^^^^^^^^^^^^
psycopg2.errors.InvalidTextRepresentation: malformed array literal: "MB"
LINE 1: ...WHERE ("products_product"."for_user_positions" @> 'MB'::varc...
                                                             ^
DETAIL:  Array value must start with "{" or dimension information.


The above exception was the direct cause of the following exception:

Traceback (most recent call last):
  File "C:\Users\Sakshham\AppData\Local\Programs\Python\Python312\Lib\site-packages\django\core\handlers\exception.py", line 55, in inner
    response = get_response(request)
               ^^^^^^^^^^^^^^^^^^^^^
  File "C:\Users\Sakshham\AppData\Local\Programs\Python\Python312\Lib\site-packages\django\core\handlers\base.py", line 197, in _get_response
    response = wrapped_callback(request, *callback_args, **callback_kwargs)
               ^^^^^^^^^^^^^^^^^^^^^^^^^^^^^^^^^^^^^^^^^^^^^^^^^^^^^^^^^^^^
  File "C:\Users\Sakshham\AppData\Local\Programs\Python\Python312\Lib\site-packages\django\views\decorators\csrf.py", line 56, in wrapper_view
    return view_func(*args, **kwargs)
           ^^^^^^^^^^^^^^^^^^^^^^^^^^
  File "C:\Users\Sakshham\AppData\Local\Programs\Python\Python312\Lib\site-packages\django\views\generic\base.py", line 104, in view
    return self.dispatch(request, *args, **kwargs)
           ^^^^^^^^^^^^^^^^^^^^^^^^^^^^^^^^^^^^^^^
  File "C:\Users\Sakshham\AppData\Local\Programs\Python\Python312\Lib\site-packages\rest_framework\views.py", line 509, in dispatch
    response = self.handle_exception(exc)
               ^^^^^^^^^^^^^^^^^^^^^^^^^^
  File "C:\Users\Sakshham\AppData\Local\Programs\Python\Python312\Lib\site-packages\rest_framework\views.py", line 469, in handle_exception
    self.raise_uncaught_exception(exc)
  File "C:\Users\Sakshham\AppData\Local\Programs\Python\Python312\Lib\site-packages\rest_framework\views.py", line 480, in raise_uncaught_exception
    raise exc
  File "C:\Users\Sakshham\AppData\Local\Programs\Python\Python312\Lib\site-packages\rest_framework\views.py", line 506, in dispatch
    response = handler(request, *args, **kwargs)
               ^^^^^^^^^^^^^^^^^^^^^^^^^^^^^^^^^
  File "D:\ALL CODES\Professional work\merch_store_backend\backend\products\views.py", line 22, in get
    return Response(serializer.data, status=status.HTTP_200_OK)
                    ^^^^^^^^^^^^^^^
  File "C:\Users\Sakshham\AppData\Local\Programs\Python\Python312\Lib\site-packages\rest_framework\serializers.py", line 795, in data
    ret = super().data
          ^^^^^^^^^^^^
  File "C:\Users\Sakshham\AppData\Local\Programs\Python\Python312\Lib\site-packages\rest_framework\serializers.py", line 249, in data
    self._data = self.to_representation(self.instance)
                 ^^^^^^^^^^^^^^^^^^^^^^^^^^^^^^^^^^^^^
  File "C:\Users\Sakshham\AppData\Local\Programs\Python\Python312\Lib\site-packages\rest_framework\serializers.py", line 713, in to_representation
    return [
           ^
  File "C:\Users\Sakshham\AppData\Local\Programs\Python\Python312\Lib\site-packages\django\db\models\query.py", line 398, in __iter__
    self._fetch_all()
  File "C:\Users\Sakshham\AppData\Local\Programs\Python\Python312\Lib\site-packages\django\db\models\query.py", line 1881, in _fetch_all
    self._result_cache = list(self._iterable_class(self))
                         ^^^^^^^^^^^^^^^^^^^^^^^^^^^^^^^^
  File "C:\Users\Sakshham\AppData\Local\Programs\Python\Python312\Lib\site-packages\django\db\models\query.py", line 91, in __iter__
    results = compiler.execute_sql(
              ^^^^^^^^^^^^^^^^^^^^^
  File "C:\Users\Sakshham\AppData\Local\Programs\Python\Python312\Lib\site-packages\django\db\models\sql\compiler.py", line 1562, in execute_sql
    cursor.execute(sql, params)
  File "C:\Users\Sakshham\AppData\Local\Programs\Python\Python312\Lib\site-packages\django\db\backends\utils.py", line 102, in execute
    return super().execute(sql, params)
           ^^^^^^^^^^^^^^^^^^^^^^^^^^^^
  File "C:\Users\Sakshham\AppData\Local\Programs\Python\Python312\Lib\site-packages\django\db\backends\utils.py", line 67, in execute
    return self._execute_with_wrappers(
           ^^^^^^^^^^^^^^^^^^^^^^^^^^^^
  File "C:\Users\Sakshham\AppData\Local\Programs\Python\Python312\Lib\site-packages\django\db\backends\utils.py", line 80, in _execute_with_wrappers
    return executor(sql, params, many, context)
           ^^^^^^^^^^^^^^^^^^^^^^^^^^^^^^^^^^^^
  File "C:\Users\Sakshham\AppData\Local\Programs\Python\Python312\Lib\site-packages\django\db\backends\utils.py", line 84, in _execute
    with self.db.wrap_database_errors:
  File "C:\Users\Sakshham\AppData\Local\Programs\Python\Python312\Lib\site-packages\django\db\utils.py", line 91, in __exit__
    raise dj_exc_value.with_traceback(traceback) from exc_value
  File "C:\Users\Sakshham\AppData\Local\Programs\Python\Python312\Lib\site-packages\django\db\backends\utils.py", line 89, in _execute
    return self.cursor.execute(sql, params)
           ^^^^^^^^^^^^^^^^^^^^^^^^^^^^^^^^
django.db.utils.DataError: malformed array literal: "MB"
LINE 1: ...WHERE ("products_product"."for_user_positions" @> 'MB'::varc...
                                                             ^
DETAIL:  Array value must start with "{" or dimension information.

[26/Jun/2024 15:37:44] ERROR [django.server:212] "GET /product/all/ HTTP/1.1" 500 171923
[04/Jul/2024 17:10:44] ERROR [django.request:241] Internal Server Error: /dashboard/
Traceback (most recent call last):
  File "C:\Users\aksha\code\merchstore\venv\lib\site-packages\django\db\backends\utils.py", line 89, in _execute
    return self.cursor.execute(sql, params)
psycopg2.errors.UndefinedTable: relation "order_order" does not exist
LINE 1: ...ELECT SUM("order_order"."amount") AS "total" FROM "order_ord...
                                                             ^


The above exception was the direct cause of the following exception:

Traceback (most recent call last):
  File "C:\Users\aksha\code\merchstore\venv\lib\site-packages\django\core\handlers\exception.py", line 55, in inner
    response = get_response(request)
  File "C:\Users\aksha\code\merchstore\venv\lib\site-packages\django\core\handlers\base.py", line 197, in _get_response
    response = wrapped_callback(request, *callback_args, **callback_kwargs)
  File "C:\Users\aksha\code\merchstore\venv\lib\site-packages\django\contrib\auth\decorators.py", line 23, in _wrapper_view
    return view_func(request, *args, **kwargs)
  File "C:\Users\aksha\code\merchstore\backend\dashboard\views.py", line 37, in dashboard
    Order.objects.filter(is_verified=True).aggregate(total=Sum("amount"))["total"]
  File "C:\Users\aksha\code\merchstore\venv\lib\site-packages\django\db\models\query.py", line 592, in aggregate
    return self.query.chain().get_aggregation(self.db, kwargs)
  File "C:\Users\aksha\code\merchstore\venv\lib\site-packages\django\db\models\sql\query.py", line 554, in get_aggregation
    result = compiler.execute_sql(SINGLE)
  File "C:\Users\aksha\code\merchstore\venv\lib\site-packages\django\db\models\sql\compiler.py", line 1562, in execute_sql
    cursor.execute(sql, params)
  File "C:\Users\aksha\code\merchstore\venv\lib\site-packages\django\db\backends\utils.py", line 102, in execute
    return super().execute(sql, params)
  File "C:\Users\aksha\code\merchstore\venv\lib\site-packages\django\db\backends\utils.py", line 67, in execute
    return self._execute_with_wrappers(
  File "C:\Users\aksha\code\merchstore\venv\lib\site-packages\django\db\backends\utils.py", line 80, in _execute_with_wrappers
    return executor(sql, params, many, context)
  File "C:\Users\aksha\code\merchstore\venv\lib\site-packages\django\db\backends\utils.py", line 89, in _execute
    return self.cursor.execute(sql, params)
  File "C:\Users\aksha\code\merchstore\venv\lib\site-packages\django\db\utils.py", line 91, in __exit__
    raise dj_exc_value.with_traceback(traceback) from exc_value
  File "C:\Users\aksha\code\merchstore\venv\lib\site-packages\django\db\backends\utils.py", line 89, in _execute
    return self.cursor.execute(sql, params)
django.db.utils.ProgrammingError: relation "order_order" does not exist
LINE 1: ...ELECT SUM("order_order"."amount") AS "total" FROM "order_ord...
                                                             ^

[04/Jul/2024 17:10:44] ERROR [django.server:212] "GET /dashboard/ HTTP/1.1" 500 129368
[04/Jul/2024 23:56:21] ERROR [django.request:241] Internal Server Error: /products/create/
Traceback (most recent call last):
  File "C:\Users\Sakshham\AppData\Local\Programs\Python\Python312\Lib\site-packages\django\db\backends\utils.py", line 89, in _execute
    return self.cursor.execute(sql, params)
           ^^^^^^^^^^^^^^^^^^^^^^^^^^^^^^^^
psycopg2.errors.NotNullViolation: null value in column "max_quantity" of relation "products_product" violates not-null constraint
DETAIL:  Failing row contains (1, Tshirt, 950.00, null, t, t, f, t, t, Tshirt hai, {}, product/Tshirt/CCS_Bulb.png, , ).


The above exception was the direct cause of the following exception:

Traceback (most recent call last):
  File "C:\Users\Sakshham\AppData\Local\Programs\Python\Python312\Lib\site-packages\django\core\handlers\exception.py", line 55, in inner
    response = get_response(request)
               ^^^^^^^^^^^^^^^^^^^^^
  File "C:\Users\Sakshham\AppData\Local\Programs\Python\Python312\Lib\site-packages\django\core\handlers\base.py", line 197, in _get_response
    response = wrapped_callback(request, *callback_args, **callback_kwargs)
               ^^^^^^^^^^^^^^^^^^^^^^^^^^^^^^^^^^^^^^^^^^^^^^^^^^^^^^^^^^^^
  File "C:\Users\Sakshham\AppData\Local\Programs\Python\Python312\Lib\site-packages\django\contrib\auth\decorators.py", line 23, in _wrapper_view
    return view_func(request, *args, **kwargs)
           ^^^^^^^^^^^^^^^^^^^^^^^^^^^^^^^^^^^
  File "D:\ALL CODES\Professional work\CCS MERCH STORE\merch_store_backend\backend\dashboard\views.py", line 268, in create_product
    product.save()
  File "C:\Users\Sakshham\AppData\Local\Programs\Python\Python312\Lib\site-packages\django\db\models\base.py", line 814, in save
    self.save_base(
  File "C:\Users\Sakshham\AppData\Local\Programs\Python\Python312\Lib\site-packages\django\db\models\base.py", line 877, in save_base
    updated = self._save_table(
              ^^^^^^^^^^^^^^^^^
  File "C:\Users\Sakshham\AppData\Local\Programs\Python\Python312\Lib\site-packages\django\db\models\base.py", line 1020, in _save_table
    results = self._do_insert(
              ^^^^^^^^^^^^^^^^
  File "C:\Users\Sakshham\AppData\Local\Programs\Python\Python312\Lib\site-packages\django\db\models\base.py", line 1061, in _do_insert
    return manager._insert(
           ^^^^^^^^^^^^^^^^
  File "C:\Users\Sakshham\AppData\Local\Programs\Python\Python312\Lib\site-packages\django\db\models\manager.py", line 87, in manager_method
    return getattr(self.get_queryset(), name)(*args, **kwargs)
           ^^^^^^^^^^^^^^^^^^^^^^^^^^^^^^^^^^^^^^^^^^^^^^^^^^^
  File "C:\Users\Sakshham\AppData\Local\Programs\Python\Python312\Lib\site-packages\django\db\models\query.py", line 1805, in _insert
    return query.get_compiler(using=using).execute_sql(returning_fields)
           ^^^^^^^^^^^^^^^^^^^^^^^^^^^^^^^^^^^^^^^^^^^^^^^^^^^^^^^^^^^^^
  File "C:\Users\Sakshham\AppData\Local\Programs\Python\Python312\Lib\site-packages\django\db\models\sql\compiler.py", line 1822, in execute_sql
    cursor.execute(sql, params)
  File "C:\Users\Sakshham\AppData\Local\Programs\Python\Python312\Lib\site-packages\django\db\backends\utils.py", line 102, in execute
    return super().execute(sql, params)
           ^^^^^^^^^^^^^^^^^^^^^^^^^^^^
  File "C:\Users\Sakshham\AppData\Local\Programs\Python\Python312\Lib\site-packages\django\db\backends\utils.py", line 67, in execute
    return self._execute_with_wrappers(
           ^^^^^^^^^^^^^^^^^^^^^^^^^^^^
  File "C:\Users\Sakshham\AppData\Local\Programs\Python\Python312\Lib\site-packages\django\db\backends\utils.py", line 80, in _execute_with_wrappers
    return executor(sql, params, many, context)
           ^^^^^^^^^^^^^^^^^^^^^^^^^^^^^^^^^^^^
  File "C:\Users\Sakshham\AppData\Local\Programs\Python\Python312\Lib\site-packages\django\db\backends\utils.py", line 84, in _execute
    with self.db.wrap_database_errors:
  File "C:\Users\Sakshham\AppData\Local\Programs\Python\Python312\Lib\site-packages\django\db\utils.py", line 91, in __exit__
    raise dj_exc_value.with_traceback(traceback) from exc_value
  File "C:\Users\Sakshham\AppData\Local\Programs\Python\Python312\Lib\site-packages\django\db\backends\utils.py", line 89, in _execute
    return self.cursor.execute(sql, params)
           ^^^^^^^^^^^^^^^^^^^^^^^^^^^^^^^^
django.db.utils.IntegrityError: null value in column "max_quantity" of relation "products_product" violates not-null constraint
DETAIL:  Failing row contains (1, Tshirt, 950.00, null, t, t, f, t, t, Tshirt hai, {}, product/Tshirt/CCS_Bulb.png, , ).

[04/Jul/2024 23:56:21] ERROR [django.server:212] "POST /products/create/ HTTP/1.1" 500 158776
[05/Jul/2024 14:11:47] ERROR [django.request:241] Internal Server Error: /cart/add
Traceback (most recent call last):
  File "C:\Users\Sakshham\AppData\Local\Programs\Python\Python312\Lib\site-packages\django\core\handlers\exception.py", line 55, in inner
    response = get_response(request)
               ^^^^^^^^^^^^^^^^^^^^^
  File "C:\Users\Sakshham\AppData\Local\Programs\Python\Python312\Lib\site-packages\django\utils\deprecation.py", line 136, in __call__
    response = self.process_response(request, response)
               ^^^^^^^^^^^^^^^^^^^^^^^^^^^^^^^^^^^^^^^^
  File "C:\Users\Sakshham\AppData\Local\Programs\Python\Python312\Lib\site-packages\django\middleware\common.py", line 108, in process_response
    return self.response_redirect_class(self.get_full_path_with_slash(request))
                                        ^^^^^^^^^^^^^^^^^^^^^^^^^^^^^^^^^^^^^^
  File "C:\Users\Sakshham\AppData\Local\Programs\Python\Python312\Lib\site-packages\django\middleware\common.py", line 87, in get_full_path_with_slash
    raise RuntimeError(
RuntimeError: You called this URL via POST, but the URL doesn't end in a slash and you have APPEND_SLASH set. Django can't redirect to the slash URL while maintaining POST data. Change your form to point to localhost:8000/cart/add/ (note the trailing slash), or set APPEND_SLASH=False in your Django settings.
[05/Jul/2024 14:11:47] ERROR [django.server:212] "POST /cart/add HTTP/1.1" 500 73946
[05/Jul/2024 14:46:27] ERROR [django.request:241] Internal Server Error: /cart/add
Traceback (most recent call last):
  File "C:\Users\Sakshham\AppData\Local\Programs\Python\Python312\Lib\site-packages\django\core\handlers\exception.py", line 55, in inner
    response = get_response(request)
               ^^^^^^^^^^^^^^^^^^^^^
  File "C:\Users\Sakshham\AppData\Local\Programs\Python\Python312\Lib\site-packages\django\utils\deprecation.py", line 136, in __call__
    response = self.process_response(request, response)
               ^^^^^^^^^^^^^^^^^^^^^^^^^^^^^^^^^^^^^^^^
  File "C:\Users\Sakshham\AppData\Local\Programs\Python\Python312\Lib\site-packages\django\middleware\common.py", line 108, in process_response
    return self.response_redirect_class(self.get_full_path_with_slash(request))
                                        ^^^^^^^^^^^^^^^^^^^^^^^^^^^^^^^^^^^^^^
  File "C:\Users\Sakshham\AppData\Local\Programs\Python\Python312\Lib\site-packages\django\middleware\common.py", line 87, in get_full_path_with_slash
    raise RuntimeError(
RuntimeError: You called this URL via POST, but the URL doesn't end in a slash and you have APPEND_SLASH set. Django can't redirect to the slash URL while maintaining POST data. Change your form to point to localhost:8000/cart/add/ (note the trailing slash), or set APPEND_SLASH=False in your Django settings.
[05/Jul/2024 14:46:27] ERROR [django.server:212] "POST /cart/add HTTP/1.1" 500 75134
[05/Jul/2024 14:46:46] ERROR [django.request:241] Internal Server Error: /cart/add
Traceback (most recent call last):
  File "C:\Users\Sakshham\AppData\Local\Programs\Python\Python312\Lib\site-packages\django\core\handlers\exception.py", line 55, in inner
    response = get_response(request)
               ^^^^^^^^^^^^^^^^^^^^^
  File "C:\Users\Sakshham\AppData\Local\Programs\Python\Python312\Lib\site-packages\django\utils\deprecation.py", line 136, in __call__
    response = self.process_response(request, response)
               ^^^^^^^^^^^^^^^^^^^^^^^^^^^^^^^^^^^^^^^^
  File "C:\Users\Sakshham\AppData\Local\Programs\Python\Python312\Lib\site-packages\django\middleware\common.py", line 108, in process_response
    return self.response_redirect_class(self.get_full_path_with_slash(request))
                                        ^^^^^^^^^^^^^^^^^^^^^^^^^^^^^^^^^^^^^^
  File "C:\Users\Sakshham\AppData\Local\Programs\Python\Python312\Lib\site-packages\django\middleware\common.py", line 87, in get_full_path_with_slash
    raise RuntimeError(
RuntimeError: You called this URL via POST, but the URL doesn't end in a slash and you have APPEND_SLASH set. Django can't redirect to the slash URL while maintaining POST data. Change your form to point to localhost:8000/cart/add/ (note the trailing slash), or set APPEND_SLASH=False in your Django settings.
[05/Jul/2024 14:46:46] ERROR [django.server:212] "POST /cart/add HTTP/1.1" 500 75134
[05/Jul/2024 17:44:13] ERROR [django.request:241] Internal Server Error: /products/create/
Traceback (most recent call last):
  File "C:\Users\Sakshham\AppData\Local\Programs\Python\Python312\Lib\site-packages\django\db\backends\utils.py", line 89, in _execute
    return self.cursor.execute(sql, params)
           ^^^^^^^^^^^^^^^^^^^^^^^^^^^^^^^^
psycopg2.errors.UniqueViolation: duplicate key value violates unique constraint "products_product_pkey"
DETAIL:  Key (id)=(3) already exists.


The above exception was the direct cause of the following exception:

Traceback (most recent call last):
  File "C:\Users\Sakshham\AppData\Local\Programs\Python\Python312\Lib\site-packages\django\core\handlers\exception.py", line 55, in inner
    response = get_response(request)
               ^^^^^^^^^^^^^^^^^^^^^
  File "C:\Users\Sakshham\AppData\Local\Programs\Python\Python312\Lib\site-packages\django\core\handlers\base.py", line 197, in _get_response
    response = wrapped_callback(request, *callback_args, **callback_kwargs)
               ^^^^^^^^^^^^^^^^^^^^^^^^^^^^^^^^^^^^^^^^^^^^^^^^^^^^^^^^^^^^
  File "C:\Users\Sakshham\AppData\Local\Programs\Python\Python312\Lib\site-packages\django\contrib\auth\decorators.py", line 23, in _wrapper_view
    return view_func(request, *args, **kwargs)
           ^^^^^^^^^^^^^^^^^^^^^^^^^^^^^^^^^^^
  File "D:\ALL CODES\Professional work\CCS MERCH STORE\merch_store_backend\backend\dashboard\views.py", line 279, in create_product
    product.save()
  File "C:\Users\Sakshham\AppData\Local\Programs\Python\Python312\Lib\site-packages\django\db\models\base.py", line 814, in save
    self.save_base(
  File "C:\Users\Sakshham\AppData\Local\Programs\Python\Python312\Lib\site-packages\django\db\models\base.py", line 877, in save_base
    updated = self._save_table(
              ^^^^^^^^^^^^^^^^^
  File "C:\Users\Sakshham\AppData\Local\Programs\Python\Python312\Lib\site-packages\django\db\models\base.py", line 1020, in _save_table
    results = self._do_insert(
              ^^^^^^^^^^^^^^^^
  File "C:\Users\Sakshham\AppData\Local\Programs\Python\Python312\Lib\site-packages\django\db\models\base.py", line 1061, in _do_insert
    return manager._insert(
           ^^^^^^^^^^^^^^^^
  File "C:\Users\Sakshham\AppData\Local\Programs\Python\Python312\Lib\site-packages\django\db\models\manager.py", line 87, in manager_method
    return getattr(self.get_queryset(), name)(*args, **kwargs)
           ^^^^^^^^^^^^^^^^^^^^^^^^^^^^^^^^^^^^^^^^^^^^^^^^^^^
  File "C:\Users\Sakshham\AppData\Local\Programs\Python\Python312\Lib\site-packages\django\db\models\query.py", line 1805, in _insert
    return query.get_compiler(using=using).execute_sql(returning_fields)
           ^^^^^^^^^^^^^^^^^^^^^^^^^^^^^^^^^^^^^^^^^^^^^^^^^^^^^^^^^^^^^
  File "C:\Users\Sakshham\AppData\Local\Programs\Python\Python312\Lib\site-packages\django\db\models\sql\compiler.py", line 1822, in execute_sql
    cursor.execute(sql, params)
  File "C:\Users\Sakshham\AppData\Local\Programs\Python\Python312\Lib\site-packages\django\db\backends\utils.py", line 102, in execute
    return super().execute(sql, params)
           ^^^^^^^^^^^^^^^^^^^^^^^^^^^^
  File "C:\Users\Sakshham\AppData\Local\Programs\Python\Python312\Lib\site-packages\django\db\backends\utils.py", line 67, in execute
    return self._execute_with_wrappers(
           ^^^^^^^^^^^^^^^^^^^^^^^^^^^^
  File "C:\Users\Sakshham\AppData\Local\Programs\Python\Python312\Lib\site-packages\django\db\backends\utils.py", line 80, in _execute_with_wrappers
    return executor(sql, params, many, context)
           ^^^^^^^^^^^^^^^^^^^^^^^^^^^^^^^^^^^^
  File "C:\Users\Sakshham\AppData\Local\Programs\Python\Python312\Lib\site-packages\django\db\backends\utils.py", line 84, in _execute
    with self.db.wrap_database_errors:
  File "C:\Users\Sakshham\AppData\Local\Programs\Python\Python312\Lib\site-packages\django\db\utils.py", line 91, in __exit__
    raise dj_exc_value.with_traceback(traceback) from exc_value
  File "C:\Users\Sakshham\AppData\Local\Programs\Python\Python312\Lib\site-packages\django\db\backends\utils.py", line 89, in _execute
    return self.cursor.execute(sql, params)
           ^^^^^^^^^^^^^^^^^^^^^^^^^^^^^^^^
django.db.utils.IntegrityError: duplicate key value violates unique constraint "products_product_pkey"
DETAIL:  Key (id)=(3) already exists.

[05/Jul/2024 17:44:13] ERROR [django.server:212] "POST /products/create/ HTTP/1.1" 500 158656
[05/Jul/2024 17:51:13] ERROR [django.request:241] Internal Server Error: /products/
Traceback (most recent call last):
  File "C:\Users\Sakshham\AppData\Local\Programs\Python\Python312\Lib\site-packages\django\core\handlers\exception.py", line 55, in inner
    response = get_response(request)
               ^^^^^^^^^^^^^^^^^^^^^
  File "C:\Users\Sakshham\AppData\Local\Programs\Python\Python312\Lib\site-packages\django\core\handlers\base.py", line 197, in _get_response
    response = wrapped_callback(request, *callback_args, **callback_kwargs)
               ^^^^^^^^^^^^^^^^^^^^^^^^^^^^^^^^^^^^^^^^^^^^^^^^^^^^^^^^^^^^
  File "C:\Users\Sakshham\AppData\Local\Programs\Python\Python312\Lib\site-packages\django\contrib\auth\decorators.py", line 23, in _wrapper_view
    return view_func(request, *args, **kwargs)
           ^^^^^^^^^^^^^^^^^^^^^^^^^^^^^^^^^^^
  File "D:\ALL CODES\Professional work\CCS MERCH STORE\merch_store_backend\backend\dashboard\views.py", line 237, in products
    return render(request, "dashboard/products.html", {"products": products})
           ^^^^^^^^^^^^^^^^^^^^^^^^^^^^^^^^^^^^^^^^^^^^^^^^^^^^^^^^^^^^^^^^^^
  File "C:\Users\Sakshham\AppData\Local\Programs\Python\Python312\Lib\site-packages\django\shortcuts.py", line 24, in render
    content = loader.render_to_string(template_name, context, request, using=using)
              ^^^^^^^^^^^^^^^^^^^^^^^^^^^^^^^^^^^^^^^^^^^^^^^^^^^^^^^^^^^^^^^^^^^^^
  File "C:\Users\Sakshham\AppData\Local\Programs\Python\Python312\Lib\site-packages\django\template\loader.py", line 61, in render_to_string
    template = get_template(template_name, using=using)
               ^^^^^^^^^^^^^^^^^^^^^^^^^^^^^^^^^^^^^^^^
  File "C:\Users\Sakshham\AppData\Local\Programs\Python\Python312\Lib\site-packages\django\template\loader.py", line 15, in get_template
    return engine.get_template(template_name)
           ^^^^^^^^^^^^^^^^^^^^^^^^^^^^^^^^^^
  File "C:\Users\Sakshham\AppData\Local\Programs\Python\Python312\Lib\site-packages\django\template\backends\django.py", line 33, in get_template
    return Template(self.engine.get_template(template_name), self)
                    ^^^^^^^^^^^^^^^^^^^^^^^^^^^^^^^^^^^^^^^
  File "C:\Users\Sakshham\AppData\Local\Programs\Python\Python312\Lib\site-packages\django\template\engine.py", line 175, in get_template
    template, origin = self.find_template(template_name)
                       ^^^^^^^^^^^^^^^^^^^^^^^^^^^^^^^^^
  File "C:\Users\Sakshham\AppData\Local\Programs\Python\Python312\Lib\site-packages\django\template\engine.py", line 157, in find_template
    template = loader.get_template(name, skip=skip)
               ^^^^^^^^^^^^^^^^^^^^^^^^^^^^^^^^^^^^
  File "C:\Users\Sakshham\AppData\Local\Programs\Python\Python312\Lib\site-packages\django\template\loaders\cached.py", line 57, in get_template
    template = super().get_template(template_name, skip)
               ^^^^^^^^^^^^^^^^^^^^^^^^^^^^^^^^^^^^^^^^^
  File "C:\Users\Sakshham\AppData\Local\Programs\Python\Python312\Lib\site-packages\django\template\loaders\base.py", line 28, in get_template
    return Template(
           ^^^^^^^^^
  File "C:\Users\Sakshham\AppData\Local\Programs\Python\Python312\Lib\site-packages\django\template\base.py", line 154, in __init__
    self.nodelist = self.compile_nodelist()
                    ^^^^^^^^^^^^^^^^^^^^^^^
  File "C:\Users\Sakshham\AppData\Local\Programs\Python\Python312\Lib\site-packages\django\template\base.py", line 200, in compile_nodelist
    return parser.parse()
           ^^^^^^^^^^^^^^
  File "C:\Users\Sakshham\AppData\Local\Programs\Python\Python312\Lib\site-packages\django\template\base.py", line 513, in parse
    raise self.error(token, e)
  File "C:\Users\Sakshham\AppData\Local\Programs\Python\Python312\Lib\site-packages\django\template\base.py", line 511, in parse
    compiled_result = compile_func(self, token)
                      ^^^^^^^^^^^^^^^^^^^^^^^^^
  File "C:\Users\Sakshham\AppData\Local\Programs\Python\Python312\Lib\site-packages\django\template\defaulttags.py", line 853, in do_for
    nodelist_loop = parser.parse(
                    ^^^^^^^^^^^^^
  File "C:\Users\Sakshham\AppData\Local\Programs\Python\Python312\Lib\site-packages\django\template\base.py", line 484, in parse
    raise self.error(token, e)
  File "C:\Users\Sakshham\AppData\Local\Programs\Python\Python312\Lib\site-packages\django\template\base.py", line 482, in parse
    filter_expression = self.compile_filter(token.contents)
                        ^^^^^^^^^^^^^^^^^^^^^^^^^^^^^^^^^^^
  File "C:\Users\Sakshham\AppData\Local\Programs\Python\Python312\Lib\site-packages\django\template\base.py", line 600, in compile_filter
    return FilterExpression(token, self)
           ^^^^^^^^^^^^^^^^^^^^^^^^^^^^^
  File "C:\Users\Sakshham\AppData\Local\Programs\Python\Python312\Lib\site-packages\django\template\base.py", line 703, in __init__
    raise TemplateSyntaxError(
django.template.exceptions.TemplateSyntaxError: Could not parse the remainder: '()' from 'product.for_user_positions.pop()'
[05/Jul/2024 17:51:13] ERROR [django.server:212] "GET /products/ HTTP/1.1" 500 201303
[05/Jul/2024 17:51:56] ERROR [django.request:241] Internal Server Error: /products/
Traceback (most recent call last):
  File "C:\Users\Sakshham\AppData\Local\Programs\Python\Python312\Lib\site-packages\django\core\handlers\exception.py", line 55, in inner
    response = get_response(request)
               ^^^^^^^^^^^^^^^^^^^^^
  File "C:\Users\Sakshham\AppData\Local\Programs\Python\Python312\Lib\site-packages\django\core\handlers\base.py", line 197, in _get_response
    response = wrapped_callback(request, *callback_args, **callback_kwargs)
               ^^^^^^^^^^^^^^^^^^^^^^^^^^^^^^^^^^^^^^^^^^^^^^^^^^^^^^^^^^^^
  File "C:\Users\Sakshham\AppData\Local\Programs\Python\Python312\Lib\site-packages\django\contrib\auth\decorators.py", line 23, in _wrapper_view
    return view_func(request, *args, **kwargs)
           ^^^^^^^^^^^^^^^^^^^^^^^^^^^^^^^^^^^
  File "D:\ALL CODES\Professional work\CCS MERCH STORE\merch_store_backend\backend\dashboard\views.py", line 237, in products
    return render(request, "dashboard/products.html", {"products": products})
           ^^^^^^^^^^^^^^^^^^^^^^^^^^^^^^^^^^^^^^^^^^^^^^^^^^^^^^^^^^^^^^^^^^
  File "C:\Users\Sakshham\AppData\Local\Programs\Python\Python312\Lib\site-packages\django\shortcuts.py", line 24, in render
    content = loader.render_to_string(template_name, context, request, using=using)
              ^^^^^^^^^^^^^^^^^^^^^^^^^^^^^^^^^^^^^^^^^^^^^^^^^^^^^^^^^^^^^^^^^^^^^
  File "C:\Users\Sakshham\AppData\Local\Programs\Python\Python312\Lib\site-packages\django\template\loader.py", line 61, in render_to_string
    template = get_template(template_name, using=using)
               ^^^^^^^^^^^^^^^^^^^^^^^^^^^^^^^^^^^^^^^^
  File "C:\Users\Sakshham\AppData\Local\Programs\Python\Python312\Lib\site-packages\django\template\loader.py", line 15, in get_template
    return engine.get_template(template_name)
           ^^^^^^^^^^^^^^^^^^^^^^^^^^^^^^^^^^
  File "C:\Users\Sakshham\AppData\Local\Programs\Python\Python312\Lib\site-packages\django\template\backends\django.py", line 33, in get_template
    return Template(self.engine.get_template(template_name), self)
                    ^^^^^^^^^^^^^^^^^^^^^^^^^^^^^^^^^^^^^^^
  File "C:\Users\Sakshham\AppData\Local\Programs\Python\Python312\Lib\site-packages\django\template\engine.py", line 175, in get_template
    template, origin = self.find_template(template_name)
                       ^^^^^^^^^^^^^^^^^^^^^^^^^^^^^^^^^
  File "C:\Users\Sakshham\AppData\Local\Programs\Python\Python312\Lib\site-packages\django\template\engine.py", line 157, in find_template
    template = loader.get_template(name, skip=skip)
               ^^^^^^^^^^^^^^^^^^^^^^^^^^^^^^^^^^^^
  File "C:\Users\Sakshham\AppData\Local\Programs\Python\Python312\Lib\site-packages\django\template\loaders\cached.py", line 57, in get_template
    template = super().get_template(template_name, skip)
               ^^^^^^^^^^^^^^^^^^^^^^^^^^^^^^^^^^^^^^^^^
  File "C:\Users\Sakshham\AppData\Local\Programs\Python\Python312\Lib\site-packages\django\template\loaders\base.py", line 28, in get_template
    return Template(
           ^^^^^^^^^
  File "C:\Users\Sakshham\AppData\Local\Programs\Python\Python312\Lib\site-packages\django\template\base.py", line 154, in __init__
    self.nodelist = self.compile_nodelist()
                    ^^^^^^^^^^^^^^^^^^^^^^^
  File "C:\Users\Sakshham\AppData\Local\Programs\Python\Python312\Lib\site-packages\django\template\base.py", line 200, in compile_nodelist
    return parser.parse()
           ^^^^^^^^^^^^^^
  File "C:\Users\Sakshham\AppData\Local\Programs\Python\Python312\Lib\site-packages\django\template\base.py", line 513, in parse
    raise self.error(token, e)
  File "C:\Users\Sakshham\AppData\Local\Programs\Python\Python312\Lib\site-packages\django\template\base.py", line 511, in parse
    compiled_result = compile_func(self, token)
                      ^^^^^^^^^^^^^^^^^^^^^^^^^
  File "C:\Users\Sakshham\AppData\Local\Programs\Python\Python312\Lib\site-packages\django\template\defaulttags.py", line 853, in do_for
    nodelist_loop = parser.parse(
                    ^^^^^^^^^^^^^
  File "C:\Users\Sakshham\AppData\Local\Programs\Python\Python312\Lib\site-packages\django\template\base.py", line 484, in parse
    raise self.error(token, e)
  File "C:\Users\Sakshham\AppData\Local\Programs\Python\Python312\Lib\site-packages\django\template\base.py", line 482, in parse
    filter_expression = self.compile_filter(token.contents)
                        ^^^^^^^^^^^^^^^^^^^^^^^^^^^^^^^^^^^
  File "C:\Users\Sakshham\AppData\Local\Programs\Python\Python312\Lib\site-packages\django\template\base.py", line 600, in compile_filter
    return FilterExpression(token, self)
           ^^^^^^^^^^^^^^^^^^^^^^^^^^^^^
  File "C:\Users\Sakshham\AppData\Local\Programs\Python\Python312\Lib\site-packages\django\template\base.py", line 703, in __init__
    raise TemplateSyntaxError(
django.template.exceptions.TemplateSyntaxError: Could not parse the remainder: '[-1]' from 'product.for_user_positions[-1]'
[05/Jul/2024 17:51:56] ERROR [django.server:212] "GET /products/ HTTP/1.1" 500 201291
[05/Jul/2024 17:52:08] ERROR [django.request:241] Internal Server Error: /products/
Traceback (most recent call last):
  File "C:\Users\Sakshham\AppData\Local\Programs\Python\Python312\Lib\site-packages\django\core\handlers\exception.py", line 55, in inner
    response = get_response(request)
               ^^^^^^^^^^^^^^^^^^^^^
  File "C:\Users\Sakshham\AppData\Local\Programs\Python\Python312\Lib\site-packages\django\core\handlers\base.py", line 197, in _get_response
    response = wrapped_callback(request, *callback_args, **callback_kwargs)
               ^^^^^^^^^^^^^^^^^^^^^^^^^^^^^^^^^^^^^^^^^^^^^^^^^^^^^^^^^^^^
  File "C:\Users\Sakshham\AppData\Local\Programs\Python\Python312\Lib\site-packages\django\contrib\auth\decorators.py", line 23, in _wrapper_view
    return view_func(request, *args, **kwargs)
           ^^^^^^^^^^^^^^^^^^^^^^^^^^^^^^^^^^^
  File "D:\ALL CODES\Professional work\CCS MERCH STORE\merch_store_backend\backend\dashboard\views.py", line 237, in products
    return render(request, "dashboard/products.html", {"products": products})
           ^^^^^^^^^^^^^^^^^^^^^^^^^^^^^^^^^^^^^^^^^^^^^^^^^^^^^^^^^^^^^^^^^^
  File "C:\Users\Sakshham\AppData\Local\Programs\Python\Python312\Lib\site-packages\django\shortcuts.py", line 24, in render
    content = loader.render_to_string(template_name, context, request, using=using)
              ^^^^^^^^^^^^^^^^^^^^^^^^^^^^^^^^^^^^^^^^^^^^^^^^^^^^^^^^^^^^^^^^^^^^^
  File "C:\Users\Sakshham\AppData\Local\Programs\Python\Python312\Lib\site-packages\django\template\loader.py", line 61, in render_to_string
    template = get_template(template_name, using=using)
               ^^^^^^^^^^^^^^^^^^^^^^^^^^^^^^^^^^^^^^^^
  File "C:\Users\Sakshham\AppData\Local\Programs\Python\Python312\Lib\site-packages\django\template\loader.py", line 15, in get_template
    return engine.get_template(template_name)
           ^^^^^^^^^^^^^^^^^^^^^^^^^^^^^^^^^^
  File "C:\Users\Sakshham\AppData\Local\Programs\Python\Python312\Lib\site-packages\django\template\backends\django.py", line 33, in get_template
    return Template(self.engine.get_template(template_name), self)
                    ^^^^^^^^^^^^^^^^^^^^^^^^^^^^^^^^^^^^^^^
  File "C:\Users\Sakshham\AppData\Local\Programs\Python\Python312\Lib\site-packages\django\template\engine.py", line 175, in get_template
    template, origin = self.find_template(template_name)
                       ^^^^^^^^^^^^^^^^^^^^^^^^^^^^^^^^^
  File "C:\Users\Sakshham\AppData\Local\Programs\Python\Python312\Lib\site-packages\django\template\engine.py", line 157, in find_template
    template = loader.get_template(name, skip=skip)
               ^^^^^^^^^^^^^^^^^^^^^^^^^^^^^^^^^^^^
  File "C:\Users\Sakshham\AppData\Local\Programs\Python\Python312\Lib\site-packages\django\template\loaders\cached.py", line 57, in get_template
    template = super().get_template(template_name, skip)
               ^^^^^^^^^^^^^^^^^^^^^^^^^^^^^^^^^^^^^^^^^
  File "C:\Users\Sakshham\AppData\Local\Programs\Python\Python312\Lib\site-packages\django\template\loaders\base.py", line 28, in get_template
    return Template(
           ^^^^^^^^^
  File "C:\Users\Sakshham\AppData\Local\Programs\Python\Python312\Lib\site-packages\django\template\base.py", line 154, in __init__
    self.nodelist = self.compile_nodelist()
                    ^^^^^^^^^^^^^^^^^^^^^^^
  File "C:\Users\Sakshham\AppData\Local\Programs\Python\Python312\Lib\site-packages\django\template\base.py", line 200, in compile_nodelist
    return parser.parse()
           ^^^^^^^^^^^^^^
  File "C:\Users\Sakshham\AppData\Local\Programs\Python\Python312\Lib\site-packages\django\template\base.py", line 513, in parse
    raise self.error(token, e)
  File "C:\Users\Sakshham\AppData\Local\Programs\Python\Python312\Lib\site-packages\django\template\base.py", line 511, in parse
    compiled_result = compile_func(self, token)
                      ^^^^^^^^^^^^^^^^^^^^^^^^^
  File "C:\Users\Sakshham\AppData\Local\Programs\Python\Python312\Lib\site-packages\django\template\defaulttags.py", line 853, in do_for
    nodelist_loop = parser.parse(
                    ^^^^^^^^^^^^^
  File "C:\Users\Sakshham\AppData\Local\Programs\Python\Python312\Lib\site-packages\django\template\base.py", line 484, in parse
    raise self.error(token, e)
  File "C:\Users\Sakshham\AppData\Local\Programs\Python\Python312\Lib\site-packages\django\template\base.py", line 482, in parse
    filter_expression = self.compile_filter(token.contents)
                        ^^^^^^^^^^^^^^^^^^^^^^^^^^^^^^^^^^^
  File "C:\Users\Sakshham\AppData\Local\Programs\Python\Python312\Lib\site-packages\django\template\base.py", line 600, in compile_filter
    return FilterExpression(token, self)
           ^^^^^^^^^^^^^^^^^^^^^^^^^^^^^
  File "C:\Users\Sakshham\AppData\Local\Programs\Python\Python312\Lib\site-packages\django\template\base.py", line 703, in __init__
    raise TemplateSyntaxError(
django.template.exceptions.TemplateSyntaxError: Could not parse the remainder: '[0]' from 'product.for_user_positions[0]'
[05/Jul/2024 17:52:08] ERROR [django.server:212] "GET /products/ HTTP/1.1" 500 201274
[05/Jul/2024 17:52:53] ERROR [django.request:241] Internal Server Error: /products/
Traceback (most recent call last):
  File "C:\Users\Sakshham\AppData\Local\Programs\Python\Python312\Lib\site-packages\django\core\handlers\exception.py", line 55, in inner
    response = get_response(request)
               ^^^^^^^^^^^^^^^^^^^^^
  File "C:\Users\Sakshham\AppData\Local\Programs\Python\Python312\Lib\site-packages\django\core\handlers\base.py", line 197, in _get_response
    response = wrapped_callback(request, *callback_args, **callback_kwargs)
               ^^^^^^^^^^^^^^^^^^^^^^^^^^^^^^^^^^^^^^^^^^^^^^^^^^^^^^^^^^^^
  File "C:\Users\Sakshham\AppData\Local\Programs\Python\Python312\Lib\site-packages\django\contrib\auth\decorators.py", line 23, in _wrapper_view
    return view_func(request, *args, **kwargs)
           ^^^^^^^^^^^^^^^^^^^^^^^^^^^^^^^^^^^
  File "D:\ALL CODES\Professional work\CCS MERCH STORE\merch_store_backend\backend\dashboard\views.py", line 237, in products
    return render(request, "dashboard/products.html", {"products": products})
           ^^^^^^^^^^^^^^^^^^^^^^^^^^^^^^^^^^^^^^^^^^^^^^^^^^^^^^^^^^^^^^^^^^
  File "C:\Users\Sakshham\AppData\Local\Programs\Python\Python312\Lib\site-packages\django\shortcuts.py", line 24, in render
    content = loader.render_to_string(template_name, context, request, using=using)
              ^^^^^^^^^^^^^^^^^^^^^^^^^^^^^^^^^^^^^^^^^^^^^^^^^^^^^^^^^^^^^^^^^^^^^
  File "C:\Users\Sakshham\AppData\Local\Programs\Python\Python312\Lib\site-packages\django\template\loader.py", line 61, in render_to_string
    template = get_template(template_name, using=using)
               ^^^^^^^^^^^^^^^^^^^^^^^^^^^^^^^^^^^^^^^^
  File "C:\Users\Sakshham\AppData\Local\Programs\Python\Python312\Lib\site-packages\django\template\loader.py", line 15, in get_template
    return engine.get_template(template_name)
           ^^^^^^^^^^^^^^^^^^^^^^^^^^^^^^^^^^
  File "C:\Users\Sakshham\AppData\Local\Programs\Python\Python312\Lib\site-packages\django\template\backends\django.py", line 33, in get_template
    return Template(self.engine.get_template(template_name), self)
                    ^^^^^^^^^^^^^^^^^^^^^^^^^^^^^^^^^^^^^^^
  File "C:\Users\Sakshham\AppData\Local\Programs\Python\Python312\Lib\site-packages\django\template\engine.py", line 175, in get_template
    template, origin = self.find_template(template_name)
                       ^^^^^^^^^^^^^^^^^^^^^^^^^^^^^^^^^
  File "C:\Users\Sakshham\AppData\Local\Programs\Python\Python312\Lib\site-packages\django\template\engine.py", line 157, in find_template
    template = loader.get_template(name, skip=skip)
               ^^^^^^^^^^^^^^^^^^^^^^^^^^^^^^^^^^^^
  File "C:\Users\Sakshham\AppData\Local\Programs\Python\Python312\Lib\site-packages\django\template\loaders\cached.py", line 57, in get_template
    template = super().get_template(template_name, skip)
               ^^^^^^^^^^^^^^^^^^^^^^^^^^^^^^^^^^^^^^^^^
  File "C:\Users\Sakshham\AppData\Local\Programs\Python\Python312\Lib\site-packages\django\template\loaders\base.py", line 28, in get_template
    return Template(
           ^^^^^^^^^
  File "C:\Users\Sakshham\AppData\Local\Programs\Python\Python312\Lib\site-packages\django\template\base.py", line 154, in __init__
    self.nodelist = self.compile_nodelist()
                    ^^^^^^^^^^^^^^^^^^^^^^^
  File "C:\Users\Sakshham\AppData\Local\Programs\Python\Python312\Lib\site-packages\django\template\base.py", line 200, in compile_nodelist
    return parser.parse()
           ^^^^^^^^^^^^^^
  File "C:\Users\Sakshham\AppData\Local\Programs\Python\Python312\Lib\site-packages\django\template\base.py", line 513, in parse
    raise self.error(token, e)
  File "C:\Users\Sakshham\AppData\Local\Programs\Python\Python312\Lib\site-packages\django\template\base.py", line 511, in parse
    compiled_result = compile_func(self, token)
                      ^^^^^^^^^^^^^^^^^^^^^^^^^
  File "C:\Users\Sakshham\AppData\Local\Programs\Python\Python312\Lib\site-packages\django\template\defaulttags.py", line 853, in do_for
    nodelist_loop = parser.parse(
                    ^^^^^^^^^^^^^
  File "C:\Users\Sakshham\AppData\Local\Programs\Python\Python312\Lib\site-packages\django\template\base.py", line 484, in parse
    raise self.error(token, e)
  File "C:\Users\Sakshham\AppData\Local\Programs\Python\Python312\Lib\site-packages\django\template\base.py", line 482, in parse
    filter_expression = self.compile_filter(token.contents)
                        ^^^^^^^^^^^^^^^^^^^^^^^^^^^^^^^^^^^
  File "C:\Users\Sakshham\AppData\Local\Programs\Python\Python312\Lib\site-packages\django\template\base.py", line 600, in compile_filter
    return FilterExpression(token, self)
           ^^^^^^^^^^^^^^^^^^^^^^^^^^^^^
  File "C:\Users\Sakshham\AppData\Local\Programs\Python\Python312\Lib\site-packages\django\template\base.py", line 703, in __init__
    raise TemplateSyntaxError(
django.template.exceptions.TemplateSyntaxError: Could not parse the remainder: '-1' from 'product.for_user_positions.-1'
[05/Jul/2024 17:52:53] ERROR [django.server:212] "GET /products/ HTTP/1.1" 500 201271
[11/Jul/2024 20:34:51] ERROR [django.request:241] Internal Server Error: /cart/update/
Traceback (most recent call last):
  File "C:\Users\Sakshham\AppData\Local\Programs\Python\Python312\Lib\site-packages\django\core\handlers\exception.py", line 55, in inner
    response = get_response(request)
               ^^^^^^^^^^^^^^^^^^^^^
  File "C:\Users\Sakshham\AppData\Local\Programs\Python\Python312\Lib\site-packages\django\core\handlers\base.py", line 197, in _get_response
    response = wrapped_callback(request, *callback_args, **callback_kwargs)
               ^^^^^^^^^^^^^^^^^^^^^^^^^^^^^^^^^^^^^^^^^^^^^^^^^^^^^^^^^^^^
  File "C:\Users\Sakshham\AppData\Local\Programs\Python\Python312\Lib\site-packages\django\views\decorators\csrf.py", line 56, in wrapper_view
    return view_func(*args, **kwargs)
           ^^^^^^^^^^^^^^^^^^^^^^^^^^
  File "C:\Users\Sakshham\AppData\Local\Programs\Python\Python312\Lib\site-packages\django\views\generic\base.py", line 104, in view
    return self.dispatch(request, *args, **kwargs)
           ^^^^^^^^^^^^^^^^^^^^^^^^^^^^^^^^^^^^^^^
  File "C:\Users\Sakshham\AppData\Local\Programs\Python\Python312\Lib\site-packages\rest_framework\views.py", line 509, in dispatch
    response = self.handle_exception(exc)
               ^^^^^^^^^^^^^^^^^^^^^^^^^^
  File "C:\Users\Sakshham\AppData\Local\Programs\Python\Python312\Lib\site-packages\rest_framework\views.py", line 469, in handle_exception
    self.raise_uncaught_exception(exc)
  File "C:\Users\Sakshham\AppData\Local\Programs\Python\Python312\Lib\site-packages\rest_framework\views.py", line 480, in raise_uncaught_exception
    raise exc
  File "C:\Users\Sakshham\AppData\Local\Programs\Python\Python312\Lib\site-packages\rest_framework\views.py", line 506, in dispatch
    response = handler(request, *args, **kwargs)
               ^^^^^^^^^^^^^^^^^^^^^^^^^^^^^^^^^
  File "D:\ALL CODES\Professional work\CCS MERCH STORE\merch_store_backend\backend\products\views.py", line 131, in post
    if discount.is_valid() and request.user in discount.for_user_positions.all():
                                               ^^^^^^^^^^^^^^^^^^^^^^^^^^^^^^^
AttributeError: 'list' object has no attribute 'all'
[11/Jul/2024 20:34:51] ERROR [django.server:212] "POST /cart/update/ HTTP/1.1" 500 98432
[11/Jul/2024 20:34:55] ERROR [django.request:241] Internal Server Error: /cart/update/
Traceback (most recent call last):
  File "C:\Users\Sakshham\AppData\Local\Programs\Python\Python312\Lib\site-packages\django\core\handlers\exception.py", line 55, in inner
    response = get_response(request)
               ^^^^^^^^^^^^^^^^^^^^^
  File "C:\Users\Sakshham\AppData\Local\Programs\Python\Python312\Lib\site-packages\django\core\handlers\base.py", line 197, in _get_response
    response = wrapped_callback(request, *callback_args, **callback_kwargs)
               ^^^^^^^^^^^^^^^^^^^^^^^^^^^^^^^^^^^^^^^^^^^^^^^^^^^^^^^^^^^^
  File "C:\Users\Sakshham\AppData\Local\Programs\Python\Python312\Lib\site-packages\django\views\decorators\csrf.py", line 56, in wrapper_view
    return view_func(*args, **kwargs)
           ^^^^^^^^^^^^^^^^^^^^^^^^^^
  File "C:\Users\Sakshham\AppData\Local\Programs\Python\Python312\Lib\site-packages\django\views\generic\base.py", line 104, in view
    return self.dispatch(request, *args, **kwargs)
           ^^^^^^^^^^^^^^^^^^^^^^^^^^^^^^^^^^^^^^^
  File "C:\Users\Sakshham\AppData\Local\Programs\Python\Python312\Lib\site-packages\rest_framework\views.py", line 509, in dispatch
    response = self.handle_exception(exc)
               ^^^^^^^^^^^^^^^^^^^^^^^^^^
  File "C:\Users\Sakshham\AppData\Local\Programs\Python\Python312\Lib\site-packages\rest_framework\views.py", line 469, in handle_exception
    self.raise_uncaught_exception(exc)
  File "C:\Users\Sakshham\AppData\Local\Programs\Python\Python312\Lib\site-packages\rest_framework\views.py", line 480, in raise_uncaught_exception
    raise exc
  File "C:\Users\Sakshham\AppData\Local\Programs\Python\Python312\Lib\site-packages\rest_framework\views.py", line 506, in dispatch
    response = handler(request, *args, **kwargs)
               ^^^^^^^^^^^^^^^^^^^^^^^^^^^^^^^^^
  File "D:\ALL CODES\Professional work\CCS MERCH STORE\merch_store_backend\backend\products\views.py", line 131, in post
    if discount.is_valid() and request.user in discount.for_user_positions.all():
                                               ^^^^^^^^^^^^^^^^^^^^^^^^^^^^^^^
AttributeError: 'list' object has no attribute 'all'
[11/Jul/2024 20:34:55] ERROR [django.server:212] "POST /cart/update/ HTTP/1.1" 500 98432
[12/Jul/2024 20:10:59] ERROR [django.request:241] Internal Server Error: /cart/add/
Traceback (most recent call last):
  File "C:\Users\Sakshham\AppData\Local\Programs\Python\Python312\Lib\site-packages\django\db\backends\utils.py", line 89, in _execute
    return self.cursor.execute(sql, params)
           ^^^^^^^^^^^^^^^^^^^^^^^^^^^^^^^^
psycopg2.errors.StringDataRightTruncation: value too long for type character varying(5)


The above exception was the direct cause of the following exception:

Traceback (most recent call last):
  File "C:\Users\Sakshham\AppData\Local\Programs\Python\Python312\Lib\site-packages\django\core\handlers\exception.py", line 55, in inner
    response = get_response(request)
               ^^^^^^^^^^^^^^^^^^^^^
  File "C:\Users\Sakshham\AppData\Local\Programs\Python\Python312\Lib\site-packages\django\core\handlers\base.py", line 197, in _get_response
    response = wrapped_callback(request, *callback_args, **callback_kwargs)
               ^^^^^^^^^^^^^^^^^^^^^^^^^^^^^^^^^^^^^^^^^^^^^^^^^^^^^^^^^^^^
  File "C:\Users\Sakshham\AppData\Local\Programs\Python\Python312\Lib\site-packages\django\views\decorators\csrf.py", line 56, in wrapper_view
    return view_func(*args, **kwargs)
           ^^^^^^^^^^^^^^^^^^^^^^^^^^
  File "C:\Users\Sakshham\AppData\Local\Programs\Python\Python312\Lib\site-packages\django\views\generic\base.py", line 104, in view
    return self.dispatch(request, *args, **kwargs)
           ^^^^^^^^^^^^^^^^^^^^^^^^^^^^^^^^^^^^^^^
  File "C:\Users\Sakshham\AppData\Local\Programs\Python\Python312\Lib\site-packages\rest_framework\views.py", line 509, in dispatch
    response = self.handle_exception(exc)
               ^^^^^^^^^^^^^^^^^^^^^^^^^^
  File "C:\Users\Sakshham\AppData\Local\Programs\Python\Python312\Lib\site-packages\rest_framework\views.py", line 469, in handle_exception
    self.raise_uncaught_exception(exc)
  File "C:\Users\Sakshham\AppData\Local\Programs\Python\Python312\Lib\site-packages\rest_framework\views.py", line 480, in raise_uncaught_exception
    raise exc
  File "C:\Users\Sakshham\AppData\Local\Programs\Python\Python312\Lib\site-packages\rest_framework\views.py", line 506, in dispatch
    response = handler(request, *args, **kwargs)
               ^^^^^^^^^^^^^^^^^^^^^^^^^^^^^^^^^
  File "D:\ALL CODES\Professional work\CCS MERCH STORE\merch_store_backend\backend\products\views.py", line 92, in post
    cart_item.save()
  File "C:\Users\Sakshham\AppData\Local\Programs\Python\Python312\Lib\site-packages\django\db\models\base.py", line 814, in save
    self.save_base(
  File "C:\Users\Sakshham\AppData\Local\Programs\Python\Python312\Lib\site-packages\django\db\models\base.py", line 877, in save_base
    updated = self._save_table(
              ^^^^^^^^^^^^^^^^^
  File "C:\Users\Sakshham\AppData\Local\Programs\Python\Python312\Lib\site-packages\django\db\models\base.py", line 1020, in _save_table
    results = self._do_insert(
              ^^^^^^^^^^^^^^^^
  File "C:\Users\Sakshham\AppData\Local\Programs\Python\Python312\Lib\site-packages\django\db\models\base.py", line 1061, in _do_insert
    return manager._insert(
           ^^^^^^^^^^^^^^^^
  File "C:\Users\Sakshham\AppData\Local\Programs\Python\Python312\Lib\site-packages\django\db\models\manager.py", line 87, in manager_method
    return getattr(self.get_queryset(), name)(*args, **kwargs)
           ^^^^^^^^^^^^^^^^^^^^^^^^^^^^^^^^^^^^^^^^^^^^^^^^^^^
  File "C:\Users\Sakshham\AppData\Local\Programs\Python\Python312\Lib\site-packages\django\db\models\query.py", line 1805, in _insert
    return query.get_compiler(using=using).execute_sql(returning_fields)
           ^^^^^^^^^^^^^^^^^^^^^^^^^^^^^^^^^^^^^^^^^^^^^^^^^^^^^^^^^^^^^
  File "C:\Users\Sakshham\AppData\Local\Programs\Python\Python312\Lib\site-packages\django\db\models\sql\compiler.py", line 1822, in execute_sql
    cursor.execute(sql, params)
  File "C:\Users\Sakshham\AppData\Local\Programs\Python\Python312\Lib\site-packages\django\db\backends\utils.py", line 102, in execute
    return super().execute(sql, params)
           ^^^^^^^^^^^^^^^^^^^^^^^^^^^^
  File "C:\Users\Sakshham\AppData\Local\Programs\Python\Python312\Lib\site-packages\django\db\backends\utils.py", line 67, in execute
    return self._execute_with_wrappers(
           ^^^^^^^^^^^^^^^^^^^^^^^^^^^^
  File "C:\Users\Sakshham\AppData\Local\Programs\Python\Python312\Lib\site-packages\django\db\backends\utils.py", line 80, in _execute_with_wrappers
    return executor(sql, params, many, context)
           ^^^^^^^^^^^^^^^^^^^^^^^^^^^^^^^^^^^^
  File "C:\Users\Sakshham\AppData\Local\Programs\Python\Python312\Lib\site-packages\django\db\backends\utils.py", line 84, in _execute
    with self.db.wrap_database_errors:
  File "C:\Users\Sakshham\AppData\Local\Programs\Python\Python312\Lib\site-packages\django\db\utils.py", line 91, in __exit__
    raise dj_exc_value.with_traceback(traceback) from exc_value
  File "C:\Users\Sakshham\AppData\Local\Programs\Python\Python312\Lib\site-packages\django\db\backends\utils.py", line 89, in _execute
    return self.cursor.execute(sql, params)
           ^^^^^^^^^^^^^^^^^^^^^^^^^^^^^^^^
django.db.utils.DataError: value too long for type character varying(5)

[12/Jul/2024 20:10:59] ERROR [django.server:212] "POST /cart/add/ HTTP/1.1" 500 174962
[12/Jul/2024 20:11:00] ERROR [django.request:241] Internal Server Error: /cart/add/
Traceback (most recent call last):
  File "C:\Users\Sakshham\AppData\Local\Programs\Python\Python312\Lib\site-packages\django\db\backends\utils.py", line 89, in _execute
    return self.cursor.execute(sql, params)
           ^^^^^^^^^^^^^^^^^^^^^^^^^^^^^^^^
psycopg2.errors.StringDataRightTruncation: value too long for type character varying(5)


The above exception was the direct cause of the following exception:

Traceback (most recent call last):
  File "C:\Users\Sakshham\AppData\Local\Programs\Python\Python312\Lib\site-packages\django\core\handlers\exception.py", line 55, in inner
    response = get_response(request)
               ^^^^^^^^^^^^^^^^^^^^^
  File "C:\Users\Sakshham\AppData\Local\Programs\Python\Python312\Lib\site-packages\django\core\handlers\base.py", line 197, in _get_response
    response = wrapped_callback(request, *callback_args, **callback_kwargs)
               ^^^^^^^^^^^^^^^^^^^^^^^^^^^^^^^^^^^^^^^^^^^^^^^^^^^^^^^^^^^^
  File "C:\Users\Sakshham\AppData\Local\Programs\Python\Python312\Lib\site-packages\django\views\decorators\csrf.py", line 56, in wrapper_view
    return view_func(*args, **kwargs)
           ^^^^^^^^^^^^^^^^^^^^^^^^^^
  File "C:\Users\Sakshham\AppData\Local\Programs\Python\Python312\Lib\site-packages\django\views\generic\base.py", line 104, in view
    return self.dispatch(request, *args, **kwargs)
           ^^^^^^^^^^^^^^^^^^^^^^^^^^^^^^^^^^^^^^^
  File "C:\Users\Sakshham\AppData\Local\Programs\Python\Python312\Lib\site-packages\rest_framework\views.py", line 509, in dispatch
    response = self.handle_exception(exc)
               ^^^^^^^^^^^^^^^^^^^^^^^^^^
  File "C:\Users\Sakshham\AppData\Local\Programs\Python\Python312\Lib\site-packages\rest_framework\views.py", line 469, in handle_exception
    self.raise_uncaught_exception(exc)
  File "C:\Users\Sakshham\AppData\Local\Programs\Python\Python312\Lib\site-packages\rest_framework\views.py", line 480, in raise_uncaught_exception
    raise exc
  File "C:\Users\Sakshham\AppData\Local\Programs\Python\Python312\Lib\site-packages\rest_framework\views.py", line 506, in dispatch
    response = handler(request, *args, **kwargs)
               ^^^^^^^^^^^^^^^^^^^^^^^^^^^^^^^^^
  File "D:\ALL CODES\Professional work\CCS MERCH STORE\merch_store_backend\backend\products\views.py", line 92, in post
    cart_item.save()
  File "C:\Users\Sakshham\AppData\Local\Programs\Python\Python312\Lib\site-packages\django\db\models\base.py", line 814, in save
    self.save_base(
  File "C:\Users\Sakshham\AppData\Local\Programs\Python\Python312\Lib\site-packages\django\db\models\base.py", line 877, in save_base
    updated = self._save_table(
              ^^^^^^^^^^^^^^^^^
  File "C:\Users\Sakshham\AppData\Local\Programs\Python\Python312\Lib\site-packages\django\db\models\base.py", line 1020, in _save_table
    results = self._do_insert(
              ^^^^^^^^^^^^^^^^
  File "C:\Users\Sakshham\AppData\Local\Programs\Python\Python312\Lib\site-packages\django\db\models\base.py", line 1061, in _do_insert
    return manager._insert(
           ^^^^^^^^^^^^^^^^
  File "C:\Users\Sakshham\AppData\Local\Programs\Python\Python312\Lib\site-packages\django\db\models\manager.py", line 87, in manager_method
    return getattr(self.get_queryset(), name)(*args, **kwargs)
           ^^^^^^^^^^^^^^^^^^^^^^^^^^^^^^^^^^^^^^^^^^^^^^^^^^^
  File "C:\Users\Sakshham\AppData\Local\Programs\Python\Python312\Lib\site-packages\django\db\models\query.py", line 1805, in _insert
    return query.get_compiler(using=using).execute_sql(returning_fields)
           ^^^^^^^^^^^^^^^^^^^^^^^^^^^^^^^^^^^^^^^^^^^^^^^^^^^^^^^^^^^^^
  File "C:\Users\Sakshham\AppData\Local\Programs\Python\Python312\Lib\site-packages\django\db\models\sql\compiler.py", line 1822, in execute_sql
    cursor.execute(sql, params)
  File "C:\Users\Sakshham\AppData\Local\Programs\Python\Python312\Lib\site-packages\django\db\backends\utils.py", line 102, in execute
    return super().execute(sql, params)
           ^^^^^^^^^^^^^^^^^^^^^^^^^^^^
  File "C:\Users\Sakshham\AppData\Local\Programs\Python\Python312\Lib\site-packages\django\db\backends\utils.py", line 67, in execute
    return self._execute_with_wrappers(
           ^^^^^^^^^^^^^^^^^^^^^^^^^^^^
  File "C:\Users\Sakshham\AppData\Local\Programs\Python\Python312\Lib\site-packages\django\db\backends\utils.py", line 80, in _execute_with_wrappers
    return executor(sql, params, many, context)
           ^^^^^^^^^^^^^^^^^^^^^^^^^^^^^^^^^^^^
  File "C:\Users\Sakshham\AppData\Local\Programs\Python\Python312\Lib\site-packages\django\db\backends\utils.py", line 84, in _execute
    with self.db.wrap_database_errors:
  File "C:\Users\Sakshham\AppData\Local\Programs\Python\Python312\Lib\site-packages\django\db\utils.py", line 91, in __exit__
    raise dj_exc_value.with_traceback(traceback) from exc_value
  File "C:\Users\Sakshham\AppData\Local\Programs\Python\Python312\Lib\site-packages\django\db\backends\utils.py", line 89, in _execute
    return self.cursor.execute(sql, params)
           ^^^^^^^^^^^^^^^^^^^^^^^^^^^^^^^^
django.db.utils.DataError: value too long for type character varying(5)

[12/Jul/2024 20:11:00] ERROR [django.server:212] "POST /cart/add/ HTTP/1.1" 500 174955
[12/Jul/2024 20:11:00] ERROR [django.request:241] Internal Server Error: /cart/add/
Traceback (most recent call last):
  File "C:\Users\Sakshham\AppData\Local\Programs\Python\Python312\Lib\site-packages\django\db\backends\utils.py", line 89, in _execute
    return self.cursor.execute(sql, params)
           ^^^^^^^^^^^^^^^^^^^^^^^^^^^^^^^^
psycopg2.errors.StringDataRightTruncation: value too long for type character varying(5)


The above exception was the direct cause of the following exception:

Traceback (most recent call last):
  File "C:\Users\Sakshham\AppData\Local\Programs\Python\Python312\Lib\site-packages\django\core\handlers\exception.py", line 55, in inner
    response = get_response(request)
               ^^^^^^^^^^^^^^^^^^^^^
  File "C:\Users\Sakshham\AppData\Local\Programs\Python\Python312\Lib\site-packages\django\core\handlers\base.py", line 197, in _get_response
    response = wrapped_callback(request, *callback_args, **callback_kwargs)
               ^^^^^^^^^^^^^^^^^^^^^^^^^^^^^^^^^^^^^^^^^^^^^^^^^^^^^^^^^^^^
  File "C:\Users\Sakshham\AppData\Local\Programs\Python\Python312\Lib\site-packages\django\views\decorators\csrf.py", line 56, in wrapper_view
    return view_func(*args, **kwargs)
           ^^^^^^^^^^^^^^^^^^^^^^^^^^
  File "C:\Users\Sakshham\AppData\Local\Programs\Python\Python312\Lib\site-packages\django\views\generic\base.py", line 104, in view
    return self.dispatch(request, *args, **kwargs)
           ^^^^^^^^^^^^^^^^^^^^^^^^^^^^^^^^^^^^^^^
  File "C:\Users\Sakshham\AppData\Local\Programs\Python\Python312\Lib\site-packages\rest_framework\views.py", line 509, in dispatch
    response = self.handle_exception(exc)
               ^^^^^^^^^^^^^^^^^^^^^^^^^^
  File "C:\Users\Sakshham\AppData\Local\Programs\Python\Python312\Lib\site-packages\rest_framework\views.py", line 469, in handle_exception
    self.raise_uncaught_exception(exc)
  File "C:\Users\Sakshham\AppData\Local\Programs\Python\Python312\Lib\site-packages\rest_framework\views.py", line 480, in raise_uncaught_exception
    raise exc
  File "C:\Users\Sakshham\AppData\Local\Programs\Python\Python312\Lib\site-packages\rest_framework\views.py", line 506, in dispatch
    response = handler(request, *args, **kwargs)
               ^^^^^^^^^^^^^^^^^^^^^^^^^^^^^^^^^
  File "D:\ALL CODES\Professional work\CCS MERCH STORE\merch_store_backend\backend\products\views.py", line 92, in post
    cart_item.save()
  File "C:\Users\Sakshham\AppData\Local\Programs\Python\Python312\Lib\site-packages\django\db\models\base.py", line 814, in save
    self.save_base(
  File "C:\Users\Sakshham\AppData\Local\Programs\Python\Python312\Lib\site-packages\django\db\models\base.py", line 877, in save_base
    updated = self._save_table(
              ^^^^^^^^^^^^^^^^^
  File "C:\Users\Sakshham\AppData\Local\Programs\Python\Python312\Lib\site-packages\django\db\models\base.py", line 1020, in _save_table
    results = self._do_insert(
              ^^^^^^^^^^^^^^^^
  File "C:\Users\Sakshham\AppData\Local\Programs\Python\Python312\Lib\site-packages\django\db\models\base.py", line 1061, in _do_insert
    return manager._insert(
           ^^^^^^^^^^^^^^^^
  File "C:\Users\Sakshham\AppData\Local\Programs\Python\Python312\Lib\site-packages\django\db\models\manager.py", line 87, in manager_method
    return getattr(self.get_queryset(), name)(*args, **kwargs)
           ^^^^^^^^^^^^^^^^^^^^^^^^^^^^^^^^^^^^^^^^^^^^^^^^^^^
  File "C:\Users\Sakshham\AppData\Local\Programs\Python\Python312\Lib\site-packages\django\db\models\query.py", line 1805, in _insert
    return query.get_compiler(using=using).execute_sql(returning_fields)
           ^^^^^^^^^^^^^^^^^^^^^^^^^^^^^^^^^^^^^^^^^^^^^^^^^^^^^^^^^^^^^
  File "C:\Users\Sakshham\AppData\Local\Programs\Python\Python312\Lib\site-packages\django\db\models\sql\compiler.py", line 1822, in execute_sql
    cursor.execute(sql, params)
  File "C:\Users\Sakshham\AppData\Local\Programs\Python\Python312\Lib\site-packages\django\db\backends\utils.py", line 102, in execute
    return super().execute(sql, params)
           ^^^^^^^^^^^^^^^^^^^^^^^^^^^^
  File "C:\Users\Sakshham\AppData\Local\Programs\Python\Python312\Lib\site-packages\django\db\backends\utils.py", line 67, in execute
    return self._execute_with_wrappers(
           ^^^^^^^^^^^^^^^^^^^^^^^^^^^^
  File "C:\Users\Sakshham\AppData\Local\Programs\Python\Python312\Lib\site-packages\django\db\backends\utils.py", line 80, in _execute_with_wrappers
    return executor(sql, params, many, context)
           ^^^^^^^^^^^^^^^^^^^^^^^^^^^^^^^^^^^^
  File "C:\Users\Sakshham\AppData\Local\Programs\Python\Python312\Lib\site-packages\django\db\backends\utils.py", line 84, in _execute
    with self.db.wrap_database_errors:
  File "C:\Users\Sakshham\AppData\Local\Programs\Python\Python312\Lib\site-packages\django\db\utils.py", line 91, in __exit__
    raise dj_exc_value.with_traceback(traceback) from exc_value
  File "C:\Users\Sakshham\AppData\Local\Programs\Python\Python312\Lib\site-packages\django\db\backends\utils.py", line 89, in _execute
    return self.cursor.execute(sql, params)
           ^^^^^^^^^^^^^^^^^^^^^^^^^^^^^^^^
django.db.utils.DataError: value too long for type character varying(5)

[12/Jul/2024 20:11:00] ERROR [django.server:212] "POST /cart/add/ HTTP/1.1" 500 174955
[16/Jul/2024 22:58:08] ERROR [django.request:241] Internal Server Error: /order/place/
Traceback (most recent call last):
  File "C:\Users\Sakshham\AppData\Local\Programs\Python\Python312\Lib\site-packages\django\core\handlers\exception.py", line 55, in inner
    response = get_response(request)
               ^^^^^^^^^^^^^^^^^^^^^
  File "C:\Users\Sakshham\AppData\Local\Programs\Python\Python312\Lib\site-packages\django\core\handlers\base.py", line 197, in _get_response
    response = wrapped_callback(request, *callback_args, **callback_kwargs)
               ^^^^^^^^^^^^^^^^^^^^^^^^^^^^^^^^^^^^^^^^^^^^^^^^^^^^^^^^^^^^
  File "C:\Users\Sakshham\AppData\Local\Programs\Python\Python312\Lib\site-packages\django\views\decorators\csrf.py", line 56, in wrapper_view
    return view_func(*args, **kwargs)
           ^^^^^^^^^^^^^^^^^^^^^^^^^^
  File "C:\Users\Sakshham\AppData\Local\Programs\Python\Python312\Lib\site-packages\django\views\generic\base.py", line 104, in view
    return self.dispatch(request, *args, **kwargs)
           ^^^^^^^^^^^^^^^^^^^^^^^^^^^^^^^^^^^^^^^
  File "C:\Users\Sakshham\AppData\Local\Programs\Python\Python312\Lib\site-packages\rest_framework\views.py", line 509, in dispatch
    response = self.handle_exception(exc)
               ^^^^^^^^^^^^^^^^^^^^^^^^^^
  File "C:\Users\Sakshham\AppData\Local\Programs\Python\Python312\Lib\site-packages\rest_framework\views.py", line 469, in handle_exception
    self.raise_uncaught_exception(exc)
  File "C:\Users\Sakshham\AppData\Local\Programs\Python\Python312\Lib\site-packages\rest_framework\views.py", line 480, in raise_uncaught_exception
    raise exc
  File "C:\Users\Sakshham\AppData\Local\Programs\Python\Python312\Lib\site-packages\rest_framework\views.py", line 506, in dispatch
    response = handler(request, *args, **kwargs)
               ^^^^^^^^^^^^^^^^^^^^^^^^^^^^^^^^^
  File "D:\ALL CODES\Professional work\CCS MERCH STORE\merch_store_backend\backend\order\views.py", line 115, in post
    updated_amount -= total_amount * (discount_percentage / 100)
                      ~~~~~~~~~~~~~^~~~~~~~~~~~~~~~~~~~~~~~~~~~~
TypeError: unsupported operand type(s) for *: 'decimal.Decimal' and 'float'
[16/Jul/2024 22:58:08] ERROR [django.server:212] "POST /order/place/ HTTP/1.1" 500 99040
[16/Jul/2024 23:02:52] ERROR [django.request:241] Internal Server Error: /order/place/
Traceback (most recent call last):
  File "C:\Users\Sakshham\AppData\Local\Programs\Python\Python312\Lib\site-packages\django\core\handlers\exception.py", line 55, in inner
    response = get_response(request)
               ^^^^^^^^^^^^^^^^^^^^^
  File "C:\Users\Sakshham\AppData\Local\Programs\Python\Python312\Lib\site-packages\django\core\handlers\base.py", line 197, in _get_response
    response = wrapped_callback(request, *callback_args, **callback_kwargs)
               ^^^^^^^^^^^^^^^^^^^^^^^^^^^^^^^^^^^^^^^^^^^^^^^^^^^^^^^^^^^^
  File "C:\Users\Sakshham\AppData\Local\Programs\Python\Python312\Lib\site-packages\django\views\decorators\csrf.py", line 56, in wrapper_view
    return view_func(*args, **kwargs)
           ^^^^^^^^^^^^^^^^^^^^^^^^^^
  File "C:\Users\Sakshham\AppData\Local\Programs\Python\Python312\Lib\site-packages\django\views\generic\base.py", line 104, in view
    return self.dispatch(request, *args, **kwargs)
           ^^^^^^^^^^^^^^^^^^^^^^^^^^^^^^^^^^^^^^^
  File "C:\Users\Sakshham\AppData\Local\Programs\Python\Python312\Lib\site-packages\rest_framework\views.py", line 509, in dispatch
    response = self.handle_exception(exc)
               ^^^^^^^^^^^^^^^^^^^^^^^^^^
  File "C:\Users\Sakshham\AppData\Local\Programs\Python\Python312\Lib\site-packages\rest_framework\views.py", line 469, in handle_exception
    self.raise_uncaught_exception(exc)
  File "C:\Users\Sakshham\AppData\Local\Programs\Python\Python312\Lib\site-packages\rest_framework\views.py", line 480, in raise_uncaught_exception
    raise exc
  File "C:\Users\Sakshham\AppData\Local\Programs\Python\Python312\Lib\site-packages\rest_framework\views.py", line 506, in dispatch
    response = handler(request, *args, **kwargs)
               ^^^^^^^^^^^^^^^^^^^^^^^^^^^^^^^^^
  File "D:\ALL CODES\Professional work\CCS MERCH STORE\merch_store_backend\backend\order\views.py", line 115, in post
    updated_amount -= total_amount * (discount_percentage / 100)
                      ~~~~~~~~~~~~~^~~~~~~~~~~~~~~~~~~~~~~~~~~~~
TypeError: unsupported operand type(s) for *: 'decimal.Decimal' and 'float'
[16/Jul/2024 23:02:52] ERROR [django.server:212] "POST /order/place/ HTTP/1.1" 500 99010
[16/Jul/2024 23:05:39] ERROR [django.request:241] Internal Server Error: /order/place/
Traceback (most recent call last):
  File "C:\Users\Sakshham\AppData\Local\Programs\Python\Python312\Lib\site-packages\django\core\handlers\exception.py", line 55, in inner
    response = get_response(request)
               ^^^^^^^^^^^^^^^^^^^^^
  File "C:\Users\Sakshham\AppData\Local\Programs\Python\Python312\Lib\site-packages\django\core\handlers\base.py", line 197, in _get_response
    response = wrapped_callback(request, *callback_args, **callback_kwargs)
               ^^^^^^^^^^^^^^^^^^^^^^^^^^^^^^^^^^^^^^^^^^^^^^^^^^^^^^^^^^^^
  File "C:\Users\Sakshham\AppData\Local\Programs\Python\Python312\Lib\site-packages\django\views\decorators\csrf.py", line 56, in wrapper_view
    return view_func(*args, **kwargs)
           ^^^^^^^^^^^^^^^^^^^^^^^^^^
  File "C:\Users\Sakshham\AppData\Local\Programs\Python\Python312\Lib\site-packages\django\views\generic\base.py", line 104, in view
    return self.dispatch(request, *args, **kwargs)
           ^^^^^^^^^^^^^^^^^^^^^^^^^^^^^^^^^^^^^^^
  File "C:\Users\Sakshham\AppData\Local\Programs\Python\Python312\Lib\site-packages\rest_framework\views.py", line 509, in dispatch
    response = self.handle_exception(exc)
               ^^^^^^^^^^^^^^^^^^^^^^^^^^
  File "C:\Users\Sakshham\AppData\Local\Programs\Python\Python312\Lib\site-packages\rest_framework\views.py", line 469, in handle_exception
    self.raise_uncaught_exception(exc)
  File "C:\Users\Sakshham\AppData\Local\Programs\Python\Python312\Lib\site-packages\rest_framework\views.py", line 480, in raise_uncaught_exception
    raise exc
  File "C:\Users\Sakshham\AppData\Local\Programs\Python\Python312\Lib\site-packages\rest_framework\views.py", line 506, in dispatch
    response = handler(request, *args, **kwargs)
               ^^^^^^^^^^^^^^^^^^^^^^^^^^^^^^^^^
  File "D:\ALL CODES\Professional work\CCS MERCH STORE\merch_store_backend\backend\order\views.py", line 115, in post
    updated_amount -= float(total_amount) * (discount_percentage / 100)
TypeError: unsupported operand type(s) for -=: 'decimal.Decimal' and 'float'
[16/Jul/2024 23:05:39] ERROR [django.server:212] "POST /order/place/ HTTP/1.1" 500 99044
[16/Jul/2024 23:11:47] ERROR [django.request:241] Internal Server Error: /order/place/
Traceback (most recent call last):
  File "C:\Users\Sakshham\AppData\Local\Programs\Python\Python312\Lib\site-packages\django\core\handlers\exception.py", line 55, in inner
    response = get_response(request)
               ^^^^^^^^^^^^^^^^^^^^^
  File "C:\Users\Sakshham\AppData\Local\Programs\Python\Python312\Lib\site-packages\django\core\handlers\base.py", line 197, in _get_response
    response = wrapped_callback(request, *callback_args, **callback_kwargs)
               ^^^^^^^^^^^^^^^^^^^^^^^^^^^^^^^^^^^^^^^^^^^^^^^^^^^^^^^^^^^^
  File "C:\Users\Sakshham\AppData\Local\Programs\Python\Python312\Lib\site-packages\django\views\decorators\csrf.py", line 56, in wrapper_view
    return view_func(*args, **kwargs)
           ^^^^^^^^^^^^^^^^^^^^^^^^^^
  File "C:\Users\Sakshham\AppData\Local\Programs\Python\Python312\Lib\site-packages\django\views\generic\base.py", line 104, in view
    return self.dispatch(request, *args, **kwargs)
           ^^^^^^^^^^^^^^^^^^^^^^^^^^^^^^^^^^^^^^^
  File "C:\Users\Sakshham\AppData\Local\Programs\Python\Python312\Lib\site-packages\rest_framework\views.py", line 509, in dispatch
    response = self.handle_exception(exc)
               ^^^^^^^^^^^^^^^^^^^^^^^^^^
  File "C:\Users\Sakshham\AppData\Local\Programs\Python\Python312\Lib\site-packages\rest_framework\views.py", line 469, in handle_exception
    self.raise_uncaught_exception(exc)
  File "C:\Users\Sakshham\AppData\Local\Programs\Python\Python312\Lib\site-packages\rest_framework\views.py", line 480, in raise_uncaught_exception
    raise exc
  File "C:\Users\Sakshham\AppData\Local\Programs\Python\Python312\Lib\site-packages\rest_framework\views.py", line 506, in dispatch
    response = handler(request, *args, **kwargs)
               ^^^^^^^^^^^^^^^^^^^^^^^^^^^^^^^^^
  File "D:\ALL CODES\Professional work\CCS MERCH STORE\merch_store_backend\backend\order\views.py", line 148, in post
    "order": serializer.data,
             ^^^^^^^^^^^^^^^
  File "C:\Users\Sakshham\AppData\Local\Programs\Python\Python312\Lib\site-packages\rest_framework\serializers.py", line 571, in data
    ret = super().data
          ^^^^^^^^^^^^
  File "C:\Users\Sakshham\AppData\Local\Programs\Python\Python312\Lib\site-packages\rest_framework\serializers.py", line 249, in data
    self._data = self.to_representation(self.instance)
                 ^^^^^^^^^^^^^^^^^^^^^^^^^^^^^^^^^^^^^
  File "C:\Users\Sakshham\AppData\Local\Programs\Python\Python312\Lib\site-packages\rest_framework\serializers.py", line 538, in to_representation
    ret[field.field_name] = field.to_representation(attribute)
                            ^^^^^^^^^^^^^^^^^^^^^^^^^^^^^^^^^^
  File "C:\Users\Sakshham\AppData\Local\Programs\Python\Python312\Lib\site-packages\rest_framework\fields.py", line 1872, in to_representation
    return method(value)
           ^^^^^^^^^^^^^
  File "D:\ALL CODES\Professional work\CCS MERCH STORE\merch_store_backend\backend\order\serializers.py", line 33, in get_total_amount
    return obj.total_amount
           ^^^^^^^^^^^^^^^^
  File "D:\ALL CODES\Professional work\CCS MERCH STORE\merch_store_backend\backend\order\models.py", line 22, in total_amount
    discount = total * (self.discount_code.discount_percentage / 100)
               ~~~~~~^~~~~~~~~~~~~~~~~~~~~~~~~~~~~~~~~~~~~~~~~~~~~~~~
TypeError: unsupported operand type(s) for *: 'decimal.Decimal' and 'float'
[16/Jul/2024 23:11:47] ERROR [django.server:212] "POST /order/place/ HTTP/1.1" 500 130504
[16/Jul/2024 23:12:08] ERROR [django.request:241] Internal Server Error: /order/place/
Traceback (most recent call last):
  File "C:\Users\Sakshham\AppData\Local\Programs\Python\Python312\Lib\site-packages\django\core\handlers\exception.py", line 55, in inner
    response = get_response(request)
               ^^^^^^^^^^^^^^^^^^^^^
  File "C:\Users\Sakshham\AppData\Local\Programs\Python\Python312\Lib\site-packages\django\core\handlers\base.py", line 197, in _get_response
    response = wrapped_callback(request, *callback_args, **callback_kwargs)
               ^^^^^^^^^^^^^^^^^^^^^^^^^^^^^^^^^^^^^^^^^^^^^^^^^^^^^^^^^^^^
  File "C:\Users\Sakshham\AppData\Local\Programs\Python\Python312\Lib\site-packages\django\views\decorators\csrf.py", line 56, in wrapper_view
    return view_func(*args, **kwargs)
           ^^^^^^^^^^^^^^^^^^^^^^^^^^
  File "C:\Users\Sakshham\AppData\Local\Programs\Python\Python312\Lib\site-packages\django\views\generic\base.py", line 104, in view
    return self.dispatch(request, *args, **kwargs)
           ^^^^^^^^^^^^^^^^^^^^^^^^^^^^^^^^^^^^^^^
  File "C:\Users\Sakshham\AppData\Local\Programs\Python\Python312\Lib\site-packages\rest_framework\views.py", line 509, in dispatch
    response = self.handle_exception(exc)
               ^^^^^^^^^^^^^^^^^^^^^^^^^^
  File "C:\Users\Sakshham\AppData\Local\Programs\Python\Python312\Lib\site-packages\rest_framework\views.py", line 469, in handle_exception
    self.raise_uncaught_exception(exc)
  File "C:\Users\Sakshham\AppData\Local\Programs\Python\Python312\Lib\site-packages\rest_framework\views.py", line 480, in raise_uncaught_exception
    raise exc
  File "C:\Users\Sakshham\AppData\Local\Programs\Python\Python312\Lib\site-packages\rest_framework\views.py", line 506, in dispatch
    response = handler(request, *args, **kwargs)
               ^^^^^^^^^^^^^^^^^^^^^^^^^^^^^^^^^
  File "D:\ALL CODES\Professional work\CCS MERCH STORE\merch_store_backend\backend\order\views.py", line 148, in post
    "order": serializer.data,
             ^^^^^^^^^^^^^^^
  File "C:\Users\Sakshham\AppData\Local\Programs\Python\Python312\Lib\site-packages\rest_framework\serializers.py", line 571, in data
    ret = super().data
          ^^^^^^^^^^^^
  File "C:\Users\Sakshham\AppData\Local\Programs\Python\Python312\Lib\site-packages\rest_framework\serializers.py", line 249, in data
    self._data = self.to_representation(self.instance)
                 ^^^^^^^^^^^^^^^^^^^^^^^^^^^^^^^^^^^^^
  File "C:\Users\Sakshham\AppData\Local\Programs\Python\Python312\Lib\site-packages\rest_framework\serializers.py", line 538, in to_representation
    ret[field.field_name] = field.to_representation(attribute)
                            ^^^^^^^^^^^^^^^^^^^^^^^^^^^^^^^^^^
  File "C:\Users\Sakshham\AppData\Local\Programs\Python\Python312\Lib\site-packages\rest_framework\fields.py", line 1872, in to_representation
    return method(value)
           ^^^^^^^^^^^^^
  File "D:\ALL CODES\Professional work\CCS MERCH STORE\merch_store_backend\backend\order\serializers.py", line 33, in get_total_amount
    return obj.total_amount
           ^^^^^^^^^^^^^^^^
  File "D:\ALL CODES\Professional work\CCS MERCH STORE\merch_store_backend\backend\order\models.py", line 22, in total_amount
    discount = total * (self.discount_code.discount_percentage / 100)
               ~~~~~~^~~~~~~~~~~~~~~~~~~~~~~~~~~~~~~~~~~~~~~~~~~~~~~~
TypeError: unsupported operand type(s) for *: 'decimal.Decimal' and 'float'
[16/Jul/2024 23:12:08] ERROR [django.server:212] "POST /order/place/ HTTP/1.1" 500 130504
[16/Jul/2024 23:13:41] ERROR [django.request:241] Internal Server Error: /order/place/
Traceback (most recent call last):
  File "C:\Users\Sakshham\AppData\Local\Programs\Python\Python312\Lib\site-packages\django\core\handlers\exception.py", line 55, in inner
    response = get_response(request)
               ^^^^^^^^^^^^^^^^^^^^^
  File "C:\Users\Sakshham\AppData\Local\Programs\Python\Python312\Lib\site-packages\django\core\handlers\base.py", line 197, in _get_response
    response = wrapped_callback(request, *callback_args, **callback_kwargs)
               ^^^^^^^^^^^^^^^^^^^^^^^^^^^^^^^^^^^^^^^^^^^^^^^^^^^^^^^^^^^^
  File "C:\Users\Sakshham\AppData\Local\Programs\Python\Python312\Lib\site-packages\django\views\decorators\csrf.py", line 56, in wrapper_view
    return view_func(*args, **kwargs)
           ^^^^^^^^^^^^^^^^^^^^^^^^^^
  File "C:\Users\Sakshham\AppData\Local\Programs\Python\Python312\Lib\site-packages\django\views\generic\base.py", line 104, in view
    return self.dispatch(request, *args, **kwargs)
           ^^^^^^^^^^^^^^^^^^^^^^^^^^^^^^^^^^^^^^^
  File "C:\Users\Sakshham\AppData\Local\Programs\Python\Python312\Lib\site-packages\rest_framework\views.py", line 509, in dispatch
    response = self.handle_exception(exc)
               ^^^^^^^^^^^^^^^^^^^^^^^^^^
  File "C:\Users\Sakshham\AppData\Local\Programs\Python\Python312\Lib\site-packages\rest_framework\views.py", line 469, in handle_exception
    self.raise_uncaught_exception(exc)
  File "C:\Users\Sakshham\AppData\Local\Programs\Python\Python312\Lib\site-packages\rest_framework\views.py", line 480, in raise_uncaught_exception
    raise exc
  File "C:\Users\Sakshham\AppData\Local\Programs\Python\Python312\Lib\site-packages\rest_framework\views.py", line 506, in dispatch
    response = handler(request, *args, **kwargs)
               ^^^^^^^^^^^^^^^^^^^^^^^^^^^^^^^^^
  File "D:\ALL CODES\Professional work\CCS MERCH STORE\merch_store_backend\backend\order\views.py", line 148, in post
    "order": serializer.data,
             ^^^^^^^^^^^^^^^
  File "C:\Users\Sakshham\AppData\Local\Programs\Python\Python312\Lib\site-packages\rest_framework\serializers.py", line 571, in data
    ret = super().data
          ^^^^^^^^^^^^
  File "C:\Users\Sakshham\AppData\Local\Programs\Python\Python312\Lib\site-packages\rest_framework\serializers.py", line 249, in data
    self._data = self.to_representation(self.instance)
                 ^^^^^^^^^^^^^^^^^^^^^^^^^^^^^^^^^^^^^
  File "C:\Users\Sakshham\AppData\Local\Programs\Python\Python312\Lib\site-packages\rest_framework\serializers.py", line 538, in to_representation
    ret[field.field_name] = field.to_representation(attribute)
                            ^^^^^^^^^^^^^^^^^^^^^^^^^^^^^^^^^^
  File "C:\Users\Sakshham\AppData\Local\Programs\Python\Python312\Lib\site-packages\rest_framework\fields.py", line 1872, in to_representation
    return method(value)
           ^^^^^^^^^^^^^
  File "D:\ALL CODES\Professional work\CCS MERCH STORE\merch_store_backend\backend\order\serializers.py", line 33, in get_total_amount
    return obj.total_amount
           ^^^^^^^^^^^^^^^^
  File "D:\ALL CODES\Professional work\CCS MERCH STORE\merch_store_backend\backend\order\models.py", line 22, in total_amount
    discount = total * (self.discount_code.discount_percentage / 100)
               ~~~~~~^~~~~~~~~~~~~~~~~~~~~~~~~~~~~~~~~~~~~~~~~~~~~~~~
TypeError: unsupported operand type(s) for *: 'decimal.Decimal' and 'float'
[16/Jul/2024 23:13:41] ERROR [django.server:212] "POST /order/place/ HTTP/1.1" 500 130504
[16/Jul/2024 23:16:51] ERROR [django.request:241] Internal Server Error: /order/place/
Traceback (most recent call last):
  File "C:\Users\Sakshham\AppData\Local\Programs\Python\Python312\Lib\site-packages\django\core\handlers\exception.py", line 55, in inner
    response = get_response(request)
               ^^^^^^^^^^^^^^^^^^^^^
  File "C:\Users\Sakshham\AppData\Local\Programs\Python\Python312\Lib\site-packages\django\core\handlers\base.py", line 197, in _get_response
    response = wrapped_callback(request, *callback_args, **callback_kwargs)
               ^^^^^^^^^^^^^^^^^^^^^^^^^^^^^^^^^^^^^^^^^^^^^^^^^^^^^^^^^^^^
  File "C:\Users\Sakshham\AppData\Local\Programs\Python\Python312\Lib\site-packages\django\views\decorators\csrf.py", line 56, in wrapper_view
    return view_func(*args, **kwargs)
           ^^^^^^^^^^^^^^^^^^^^^^^^^^
  File "C:\Users\Sakshham\AppData\Local\Programs\Python\Python312\Lib\site-packages\django\views\generic\base.py", line 104, in view
    return self.dispatch(request, *args, **kwargs)
           ^^^^^^^^^^^^^^^^^^^^^^^^^^^^^^^^^^^^^^^
  File "C:\Users\Sakshham\AppData\Local\Programs\Python\Python312\Lib\site-packages\rest_framework\views.py", line 509, in dispatch
    response = self.handle_exception(exc)
               ^^^^^^^^^^^^^^^^^^^^^^^^^^
  File "C:\Users\Sakshham\AppData\Local\Programs\Python\Python312\Lib\site-packages\rest_framework\views.py", line 469, in handle_exception
    self.raise_uncaught_exception(exc)
  File "C:\Users\Sakshham\AppData\Local\Programs\Python\Python312\Lib\site-packages\rest_framework\views.py", line 480, in raise_uncaught_exception
    raise exc
  File "C:\Users\Sakshham\AppData\Local\Programs\Python\Python312\Lib\site-packages\rest_framework\views.py", line 506, in dispatch
    response = handler(request, *args, **kwargs)
               ^^^^^^^^^^^^^^^^^^^^^^^^^^^^^^^^^
  File "D:\ALL CODES\Professional work\CCS MERCH STORE\merch_store_backend\backend\order\views.py", line 148, in post
    "order": serializer.data,
             ^^^^^^^^^^^^^^^
  File "C:\Users\Sakshham\AppData\Local\Programs\Python\Python312\Lib\site-packages\rest_framework\serializers.py", line 571, in data
    ret = super().data
          ^^^^^^^^^^^^
  File "C:\Users\Sakshham\AppData\Local\Programs\Python\Python312\Lib\site-packages\rest_framework\serializers.py", line 249, in data
    self._data = self.to_representation(self.instance)
                 ^^^^^^^^^^^^^^^^^^^^^^^^^^^^^^^^^^^^^
  File "C:\Users\Sakshham\AppData\Local\Programs\Python\Python312\Lib\site-packages\rest_framework\serializers.py", line 538, in to_representation
    ret[field.field_name] = field.to_representation(attribute)
                            ^^^^^^^^^^^^^^^^^^^^^^^^^^^^^^^^^^
  File "C:\Users\Sakshham\AppData\Local\Programs\Python\Python312\Lib\site-packages\rest_framework\fields.py", line 1872, in to_representation
    return method(value)
           ^^^^^^^^^^^^^
  File "D:\ALL CODES\Professional work\CCS MERCH STORE\merch_store_backend\backend\order\serializers.py", line 33, in get_total_amount
    return obj.total_amount
           ^^^^^^^^^^^^^^^^
  File "D:\ALL CODES\Professional work\CCS MERCH STORE\merch_store_backend\backend\order\models.py", line 22, in total_amount
    discount = total * (self.discount_code.discount_percentage / 100)
               ~~~~~~^~~~~~~~~~~~~~~~~~~~~~~~~~~~~~~~~~~~~~~~~~~~~~~~
TypeError: unsupported operand type(s) for *: 'decimal.Decimal' and 'float'
[16/Jul/2024 23:16:51] ERROR [django.server:212] "POST /order/place/ HTTP/1.1" 500 130504
[16/Jul/2024 23:18:25] ERROR [django.request:241] Internal Server Error: /order/place/
Traceback (most recent call last):
  File "C:\Users\Sakshham\AppData\Local\Programs\Python\Python312\Lib\site-packages\django\core\handlers\exception.py", line 55, in inner
    response = get_response(request)
               ^^^^^^^^^^^^^^^^^^^^^
  File "C:\Users\Sakshham\AppData\Local\Programs\Python\Python312\Lib\site-packages\django\core\handlers\base.py", line 197, in _get_response
    response = wrapped_callback(request, *callback_args, **callback_kwargs)
               ^^^^^^^^^^^^^^^^^^^^^^^^^^^^^^^^^^^^^^^^^^^^^^^^^^^^^^^^^^^^
  File "C:\Users\Sakshham\AppData\Local\Programs\Python\Python312\Lib\site-packages\django\views\decorators\csrf.py", line 56, in wrapper_view
    return view_func(*args, **kwargs)
           ^^^^^^^^^^^^^^^^^^^^^^^^^^
  File "C:\Users\Sakshham\AppData\Local\Programs\Python\Python312\Lib\site-packages\django\views\generic\base.py", line 104, in view
    return self.dispatch(request, *args, **kwargs)
           ^^^^^^^^^^^^^^^^^^^^^^^^^^^^^^^^^^^^^^^
  File "C:\Users\Sakshham\AppData\Local\Programs\Python\Python312\Lib\site-packages\rest_framework\views.py", line 509, in dispatch
    response = self.handle_exception(exc)
               ^^^^^^^^^^^^^^^^^^^^^^^^^^
  File "C:\Users\Sakshham\AppData\Local\Programs\Python\Python312\Lib\site-packages\rest_framework\views.py", line 469, in handle_exception
    self.raise_uncaught_exception(exc)
  File "C:\Users\Sakshham\AppData\Local\Programs\Python\Python312\Lib\site-packages\rest_framework\views.py", line 480, in raise_uncaught_exception
    raise exc
  File "C:\Users\Sakshham\AppData\Local\Programs\Python\Python312\Lib\site-packages\rest_framework\views.py", line 506, in dispatch
    response = handler(request, *args, **kwargs)
               ^^^^^^^^^^^^^^^^^^^^^^^^^^^^^^^^^
  File "D:\ALL CODES\Professional work\CCS MERCH STORE\merch_store_backend\backend\order\views.py", line 148, in post
    "order": serializer.data,
             ^^^^^^^^^^^^^^^
  File "C:\Users\Sakshham\AppData\Local\Programs\Python\Python312\Lib\site-packages\rest_framework\serializers.py", line 571, in data
    ret = super().data
          ^^^^^^^^^^^^
  File "C:\Users\Sakshham\AppData\Local\Programs\Python\Python312\Lib\site-packages\rest_framework\serializers.py", line 249, in data
    self._data = self.to_representation(self.instance)
                 ^^^^^^^^^^^^^^^^^^^^^^^^^^^^^^^^^^^^^
  File "C:\Users\Sakshham\AppData\Local\Programs\Python\Python312\Lib\site-packages\rest_framework\serializers.py", line 538, in to_representation
    ret[field.field_name] = field.to_representation(attribute)
                            ^^^^^^^^^^^^^^^^^^^^^^^^^^^^^^^^^^
  File "C:\Users\Sakshham\AppData\Local\Programs\Python\Python312\Lib\site-packages\rest_framework\fields.py", line 1872, in to_representation
    return method(value)
           ^^^^^^^^^^^^^
  File "D:\ALL CODES\Professional work\CCS MERCH STORE\merch_store_backend\backend\order\serializers.py", line 33, in get_total_amount
    return obj.total_amount
           ^^^^^^^^^^^^^^^^
  File "D:\ALL CODES\Professional work\CCS MERCH STORE\merch_store_backend\backend\order\models.py", line 22, in total_amount
    discount = total * (self.discount_code.discount_percentage / 100)
               ~~~~~~^~~~~~~~~~~~~~~~~~~~~~~~~~~~~~~~~~~~~~~~~~~~~~~~
TypeError: unsupported operand type(s) for *: 'decimal.Decimal' and 'float'
[16/Jul/2024 23:18:25] ERROR [django.server:212] "POST /order/place/ HTTP/1.1" 500 130504
[16/Jul/2024 23:36:17] ERROR [django.request:241] Internal Server Error: /order/place/
Traceback (most recent call last):
  File "C:\Users\Sakshham\AppData\Local\Programs\Python\Python312\Lib\site-packages\django\core\handlers\exception.py", line 55, in inner
    response = get_response(request)
               ^^^^^^^^^^^^^^^^^^^^^
  File "C:\Users\Sakshham\AppData\Local\Programs\Python\Python312\Lib\site-packages\django\core\handlers\base.py", line 197, in _get_response
    response = wrapped_callback(request, *callback_args, **callback_kwargs)
               ^^^^^^^^^^^^^^^^^^^^^^^^^^^^^^^^^^^^^^^^^^^^^^^^^^^^^^^^^^^^
  File "C:\Users\Sakshham\AppData\Local\Programs\Python\Python312\Lib\site-packages\django\views\decorators\csrf.py", line 56, in wrapper_view
    return view_func(*args, **kwargs)
           ^^^^^^^^^^^^^^^^^^^^^^^^^^
  File "C:\Users\Sakshham\AppData\Local\Programs\Python\Python312\Lib\site-packages\django\views\generic\base.py", line 104, in view
    return self.dispatch(request, *args, **kwargs)
           ^^^^^^^^^^^^^^^^^^^^^^^^^^^^^^^^^^^^^^^
  File "C:\Users\Sakshham\AppData\Local\Programs\Python\Python312\Lib\site-packages\rest_framework\views.py", line 509, in dispatch
    response = self.handle_exception(exc)
               ^^^^^^^^^^^^^^^^^^^^^^^^^^
  File "C:\Users\Sakshham\AppData\Local\Programs\Python\Python312\Lib\site-packages\rest_framework\views.py", line 469, in handle_exception
    self.raise_uncaught_exception(exc)
  File "C:\Users\Sakshham\AppData\Local\Programs\Python\Python312\Lib\site-packages\rest_framework\views.py", line 480, in raise_uncaught_exception
    raise exc
  File "C:\Users\Sakshham\AppData\Local\Programs\Python\Python312\Lib\site-packages\rest_framework\views.py", line 506, in dispatch
    response = handler(request, *args, **kwargs)
               ^^^^^^^^^^^^^^^^^^^^^^^^^^^^^^^^^
  File "D:\ALL CODES\Professional work\CCS MERCH STORE\merch_store_backend\backend\order\views.py", line 153, in post
    "order": serializer.data,
             ^^^^^^^^^^^^^^^
  File "C:\Users\Sakshham\AppData\Local\Programs\Python\Python312\Lib\site-packages\rest_framework\serializers.py", line 571, in data
    ret = super().data
          ^^^^^^^^^^^^
  File "C:\Users\Sakshham\AppData\Local\Programs\Python\Python312\Lib\site-packages\rest_framework\serializers.py", line 249, in data
    self._data = self.to_representation(self.instance)
                 ^^^^^^^^^^^^^^^^^^^^^^^^^^^^^^^^^^^^^
  File "C:\Users\Sakshham\AppData\Local\Programs\Python\Python312\Lib\site-packages\rest_framework\serializers.py", line 538, in to_representation
    ret[field.field_name] = field.to_representation(attribute)
                            ^^^^^^^^^^^^^^^^^^^^^^^^^^^^^^^^^^
  File "C:\Users\Sakshham\AppData\Local\Programs\Python\Python312\Lib\site-packages\rest_framework\fields.py", line 1872, in to_representation
    return method(value)
           ^^^^^^^^^^^^^
  File "D:\ALL CODES\Professional work\CCS MERCH STORE\merch_store_backend\backend\order\serializers.py", line 33, in get_total_amount
    return obj.total_amount
           ^^^^^^^^^^^^^^^^
  File "D:\ALL CODES\Professional work\CCS MERCH STORE\merch_store_backend\backend\order\models.py", line 22, in total_amount
    discount = total * (self.discount_code.discount_percentage / 100)
               ~~~~~~^~~~~~~~~~~~~~~~~~~~~~~~~~~~~~~~~~~~~~~~~~~~~~~~
TypeError: unsupported operand type(s) for *: 'decimal.Decimal' and 'float'
[16/Jul/2024 23:36:17] ERROR [django.server:212] "POST /order/place/ HTTP/1.1" 500 130570
