[13/Aug/2024 17:14:40] ERROR [django.request:241] Internal Server Error: /dashboard/
Traceback (most recent call last):
  File "/usr/local/lib/python3.9/site-packages/django/core/files/storage/handler.py", line 35, in __getitem__
    return self._storages[alias]
KeyError: 'staticfiles'

During handling of the above exception, another exception occurred:

Traceback (most recent call last):
  File "/usr/local/lib/python3.9/site-packages/django/core/handlers/exception.py", line 55, in inner
    response = get_response(request)
  File "/usr/local/lib/python3.9/site-packages/django/core/handlers/base.py", line 197, in _get_response
    response = wrapped_callback(request, *callback_args, **callback_kwargs)
  File "/usr/local/lib/python3.9/site-packages/django/contrib/auth/decorators.py", line 23, in _wrapper_view
    return view_func(request, *args, **kwargs)
  File "/app/backend/dashboard/views.py", line 87, in dashboard
    return render(request, "dashboard/dashboard.html", context=context)
  File "/usr/local/lib/python3.9/site-packages/django/shortcuts.py", line 24, in render
    content = loader.render_to_string(template_name, context, request, using=using)
  File "/usr/local/lib/python3.9/site-packages/django/template/loader.py", line 62, in render_to_string
    return template.render(context, request)
  File "/usr/local/lib/python3.9/site-packages/django/template/backends/django.py", line 61, in render
    return self.template.render(context)
  File "/usr/local/lib/python3.9/site-packages/django/template/base.py", line 175, in render
    return self._render(context)
  File "/usr/local/lib/python3.9/site-packages/django/template/base.py", line 167, in _render
    return self.nodelist.render(context)
  File "/usr/local/lib/python3.9/site-packages/django/template/base.py", line 1005, in render
    return SafeString("".join([node.render_annotated(context) for node in self]))
  File "/usr/local/lib/python3.9/site-packages/django/template/base.py", line 1005, in <listcomp>
    return SafeString("".join([node.render_annotated(context) for node in self]))
  File "/usr/local/lib/python3.9/site-packages/django/template/base.py", line 966, in render_annotated
    return self.render(context)
  File "/usr/local/lib/python3.9/site-packages/django/templatetags/static.py", line 116, in render
    url = self.url(context)
  File "/usr/local/lib/python3.9/site-packages/django/templatetags/static.py", line 113, in url
    return self.handle_simple(path)
  File "/usr/local/lib/python3.9/site-packages/django/templatetags/static.py", line 129, in handle_simple
    return staticfiles_storage.url(path)
  File "/usr/local/lib/python3.9/site-packages/django/utils/functional.py", line 266, in inner
    self._setup()
  File "/usr/local/lib/python3.9/site-packages/django/contrib/staticfiles/storage.py", line 537, in _setup
    self._wrapped = storages[STATICFILES_STORAGE_ALIAS]
  File "/usr/local/lib/python3.9/site-packages/django/core/files/storage/handler.py", line 43, in __getitem__
    storage = self.create_storage(params)
  File "/usr/local/lib/python3.9/site-packages/django/core/files/storage/handler.py", line 55, in create_storage
    return storage_cls(**options)
  File "/usr/local/lib/python3.9/site-packages/django/contrib/staticfiles/storage.py", line 29, in __init__
    check_settings(base_url)
  File "/usr/local/lib/python3.9/site-packages/django/contrib/staticfiles/utils.py", line 49, in check_settings
    raise ImproperlyConfigured(
django.core.exceptions.ImproperlyConfigured: You're using the staticfiles app without having set the required STATIC_URL setting.
[14/Aug/2024 13:04:56] ERROR [django.request:241] Internal Server Error: /auth/login/
Traceback (most recent call last):
  File "/usr/local/lib/python3.9/site-packages/django/core/handlers/exception.py", line 55, in inner
    response = get_response(request)
  File "/usr/local/lib/python3.9/site-packages/django/core/handlers/base.py", line 197, in _get_response
    response = wrapped_callback(request, *callback_args, **callback_kwargs)
  File "/usr/local/lib/python3.9/site-packages/django/views/decorators/csrf.py", line 56, in wrapper_view
    return view_func(*args, **kwargs)
  File "/usr/local/lib/python3.9/site-packages/django/views/generic/base.py", line 104, in view
    return self.dispatch(request, *args, **kwargs)
  File "/usr/local/lib/python3.9/site-packages/rest_framework/views.py", line 509, in dispatch
    response = self.handle_exception(exc)
  File "/usr/local/lib/python3.9/site-packages/rest_framework/views.py", line 469, in handle_exception
    self.raise_uncaught_exception(exc)
  File "/usr/local/lib/python3.9/site-packages/rest_framework/views.py", line 480, in raise_uncaught_exception
    raise exc
  File "/usr/local/lib/python3.9/site-packages/rest_framework/views.py", line 506, in dispatch
    response = handler(request, *args, **kwargs)
  File "/app/backend/login/views.py", line 21, in post
    user = authenticate(request, sso_token=sso_token)
  File "/usr/local/lib/python3.9/site-packages/django/views/decorators/debug.py", line 42, in sensitive_variables_wrapper
    return func(*func_args, **func_kwargs)
  File "/usr/local/lib/python3.9/site-packages/django/contrib/auth/__init__.py", line 68, in authenticate
    for backend, backend_path in _get_backends(return_tuples=True):
  File "/usr/local/lib/python3.9/site-packages/django/contrib/auth/__init__.py", line 27, in _get_backends
    backend = load_backend(backend_path)
  File "/usr/local/lib/python3.9/site-packages/django/contrib/auth/__init__.py", line 21, in load_backend
    return import_string(path)()
  File "/usr/local/lib/python3.9/site-packages/django/utils/module_loading.py", line 30, in import_string
    return cached_import(module_path, class_name)
  File "/usr/local/lib/python3.9/site-packages/django/utils/module_loading.py", line 15, in cached_import
    module = import_module(module_path)
  File "/usr/local/lib/python3.9/importlib/__init__.py", line 127, in import_module
    return _bootstrap._gcd_import(name[level:], package, level)
  File "<frozen importlib._bootstrap>", line 1030, in _gcd_import
  File "<frozen importlib._bootstrap>", line 1007, in _find_and_load
  File "<frozen importlib._bootstrap>", line 986, in _find_and_load_unlocked
  File "<frozen importlib._bootstrap>", line 680, in _load_unlocked
  File "<frozen importlib._bootstrap_external>", line 850, in exec_module
  File "<frozen importlib._bootstrap>", line 228, in _call_with_frames_removed
  File "/app/backend/login/backend.py", line 2, in <module>
    from jwt.exceptions import ExpiredSignatureError, InvalidTokenError
ImportError: cannot import name 'ExpiredSignatureError' from 'jwt.exceptions' (/usr/local/lib/python3.9/site-packages/jwt/exceptions.py)
[14/Aug/2024 13:13:31] ERROR [django.request:241] Internal Server Error: /auth/login/
Traceback (most recent call last):
  File "/usr/local/lib/python3.9/site-packages/django/core/handlers/exception.py", line 55, in inner
    response = get_response(request)
  File "/usr/local/lib/python3.9/site-packages/django/core/handlers/base.py", line 197, in _get_response
    response = wrapped_callback(request, *callback_args, **callback_kwargs)
  File "/usr/local/lib/python3.9/site-packages/django/views/decorators/csrf.py", line 56, in wrapper_view
    return view_func(*args, **kwargs)
  File "/usr/local/lib/python3.9/site-packages/django/views/generic/base.py", line 104, in view
    return self.dispatch(request, *args, **kwargs)
  File "/usr/local/lib/python3.9/site-packages/rest_framework/views.py", line 509, in dispatch
    response = self.handle_exception(exc)
  File "/usr/local/lib/python3.9/site-packages/rest_framework/views.py", line 469, in handle_exception
    self.raise_uncaught_exception(exc)
  File "/usr/local/lib/python3.9/site-packages/rest_framework/views.py", line 480, in raise_uncaught_exception
    raise exc
  File "/usr/local/lib/python3.9/site-packages/rest_framework/views.py", line 506, in dispatch
    response = handler(request, *args, **kwargs)
  File "/app/backend/login/views.py", line 21, in post
    user = authenticate(request, sso_token=sso_token)
  File "/usr/local/lib/python3.9/site-packages/django/views/decorators/debug.py", line 42, in sensitive_variables_wrapper
    return func(*func_args, **func_kwargs)
  File "/usr/local/lib/python3.9/site-packages/django/contrib/auth/__init__.py", line 68, in authenticate
    for backend, backend_path in _get_backends(return_tuples=True):
  File "/usr/local/lib/python3.9/site-packages/django/contrib/auth/__init__.py", line 27, in _get_backends
    backend = load_backend(backend_path)
  File "/usr/local/lib/python3.9/site-packages/django/contrib/auth/__init__.py", line 21, in load_backend
    return import_string(path)()
  File "/usr/local/lib/python3.9/site-packages/django/utils/module_loading.py", line 30, in import_string
    return cached_import(module_path, class_name)
  File "/usr/local/lib/python3.9/site-packages/django/utils/module_loading.py", line 15, in cached_import
    module = import_module(module_path)
  File "/usr/local/lib/python3.9/importlib/__init__.py", line 127, in import_module
    return _bootstrap._gcd_import(name[level:], package, level)
  File "<frozen importlib._bootstrap>", line 1030, in _gcd_import
  File "<frozen importlib._bootstrap>", line 1007, in _find_and_load
  File "<frozen importlib._bootstrap>", line 986, in _find_and_load_unlocked
  File "<frozen importlib._bootstrap>", line 680, in _load_unlocked
  File "<frozen importlib._bootstrap_external>", line 850, in exec_module
  File "<frozen importlib._bootstrap>", line 228, in _call_with_frames_removed
  File "/app/backend/login/backend.py", line 2, in <module>
    from jwt import ExpiredSignatureError, InvalidTokenError
ImportError: cannot import name 'ExpiredSignatureError' from 'jwt' (/usr/local/lib/python3.9/site-packages/jwt/__init__.py)
[14/Aug/2024 13:13:52] ERROR [django.request:241] Internal Server Error: /auth/login/
Traceback (most recent call last):
  File "/usr/local/lib/python3.9/site-packages/django/core/handlers/exception.py", line 55, in inner
    response = get_response(request)
  File "/usr/local/lib/python3.9/site-packages/django/core/handlers/base.py", line 197, in _get_response
    response = wrapped_callback(request, *callback_args, **callback_kwargs)
  File "/usr/local/lib/python3.9/site-packages/django/views/decorators/csrf.py", line 56, in wrapper_view
    return view_func(*args, **kwargs)
  File "/usr/local/lib/python3.9/site-packages/django/views/generic/base.py", line 104, in view
    return self.dispatch(request, *args, **kwargs)
  File "/usr/local/lib/python3.9/site-packages/rest_framework/views.py", line 509, in dispatch
    response = self.handle_exception(exc)
  File "/usr/local/lib/python3.9/site-packages/rest_framework/views.py", line 469, in handle_exception
    self.raise_uncaught_exception(exc)
  File "/usr/local/lib/python3.9/site-packages/rest_framework/views.py", line 480, in raise_uncaught_exception
    raise exc
  File "/usr/local/lib/python3.9/site-packages/rest_framework/views.py", line 506, in dispatch
    response = handler(request, *args, **kwargs)
  File "/app/backend/login/views.py", line 21, in post
    user = authenticate(request, sso_token=sso_token)
  File "/usr/local/lib/python3.9/site-packages/django/views/decorators/debug.py", line 42, in sensitive_variables_wrapper
    return func(*func_args, **func_kwargs)
  File "/usr/local/lib/python3.9/site-packages/django/contrib/auth/__init__.py", line 68, in authenticate
    for backend, backend_path in _get_backends(return_tuples=True):
  File "/usr/local/lib/python3.9/site-packages/django/contrib/auth/__init__.py", line 27, in _get_backends
    backend = load_backend(backend_path)
  File "/usr/local/lib/python3.9/site-packages/django/contrib/auth/__init__.py", line 21, in load_backend
    return import_string(path)()
  File "/usr/local/lib/python3.9/site-packages/django/utils/module_loading.py", line 30, in import_string
    return cached_import(module_path, class_name)
  File "/usr/local/lib/python3.9/site-packages/django/utils/module_loading.py", line 15, in cached_import
    module = import_module(module_path)
  File "/usr/local/lib/python3.9/importlib/__init__.py", line 127, in import_module
    return _bootstrap._gcd_import(name[level:], package, level)
  File "<frozen importlib._bootstrap>", line 1030, in _gcd_import
  File "<frozen importlib._bootstrap>", line 1007, in _find_and_load
  File "<frozen importlib._bootstrap>", line 986, in _find_and_load_unlocked
  File "<frozen importlib._bootstrap>", line 680, in _load_unlocked
  File "<frozen importlib._bootstrap_external>", line 850, in exec_module
  File "<frozen importlib._bootstrap>", line 228, in _call_with_frames_removed
  File "/app/backend/login/backend.py", line 2, in <module>
    from jwt import ExpiredSignatureError, InvalidTokenError
ImportError: cannot import name 'ExpiredSignatureError' from 'jwt' (/usr/local/lib/python3.9/site-packages/jwt/__init__.py)
[14/Aug/2024 13:24:59] ERROR [django.request:241] Internal Server Error: /auth/login/
Traceback (most recent call last):
  File "/usr/local/lib/python3.9/site-packages/django/core/handlers/exception.py", line 55, in inner
    response = get_response(request)
  File "/usr/local/lib/python3.9/site-packages/django/core/handlers/base.py", line 197, in _get_response
    response = wrapped_callback(request, *callback_args, **callback_kwargs)
  File "/usr/local/lib/python3.9/site-packages/django/views/decorators/csrf.py", line 56, in wrapper_view
    return view_func(*args, **kwargs)
  File "/usr/local/lib/python3.9/site-packages/django/views/generic/base.py", line 104, in view
    return self.dispatch(request, *args, **kwargs)
  File "/usr/local/lib/python3.9/site-packages/rest_framework/views.py", line 509, in dispatch
    response = self.handle_exception(exc)
  File "/usr/local/lib/python3.9/site-packages/rest_framework/views.py", line 469, in handle_exception
    self.raise_uncaught_exception(exc)
  File "/usr/local/lib/python3.9/site-packages/rest_framework/views.py", line 480, in raise_uncaught_exception
    raise exc
  File "/usr/local/lib/python3.9/site-packages/rest_framework/views.py", line 506, in dispatch
    response = handler(request, *args, **kwargs)
  File "/app/backend/login/views.py", line 21, in post
    user = authenticate(request, sso_token=sso_token)
  File "/usr/local/lib/python3.9/site-packages/django/views/decorators/debug.py", line 42, in sensitive_variables_wrapper
    return func(*func_args, **func_kwargs)
  File "/usr/local/lib/python3.9/site-packages/django/contrib/auth/__init__.py", line 68, in authenticate
    for backend, backend_path in _get_backends(return_tuples=True):
  File "/usr/local/lib/python3.9/site-packages/django/contrib/auth/__init__.py", line 27, in _get_backends
    backend = load_backend(backend_path)
  File "/usr/local/lib/python3.9/site-packages/django/contrib/auth/__init__.py", line 21, in load_backend
    return import_string(path)()
  File "/usr/local/lib/python3.9/site-packages/django/utils/module_loading.py", line 30, in import_string
    return cached_import(module_path, class_name)
  File "/usr/local/lib/python3.9/site-packages/django/utils/module_loading.py", line 15, in cached_import
    module = import_module(module_path)
  File "/usr/local/lib/python3.9/importlib/__init__.py", line 127, in import_module
    return _bootstrap._gcd_import(name[level:], package, level)
  File "<frozen importlib._bootstrap>", line 1030, in _gcd_import
  File "<frozen importlib._bootstrap>", line 1007, in _find_and_load
  File "<frozen importlib._bootstrap>", line 986, in _find_and_load_unlocked
  File "<frozen importlib._bootstrap>", line 680, in _load_unlocked
  File "<frozen importlib._bootstrap_external>", line 850, in exec_module
  File "<frozen importlib._bootstrap>", line 228, in _call_with_frames_removed
  File "/app/backend/login/backend.py", line 2, in <module>
    from jwt.exceptions import ExpiredSignatureError, InvalidTokenError
ImportError: cannot import name 'ExpiredSignatureError' from 'jwt.exceptions' (/usr/local/lib/python3.9/site-packages/jwt/exceptions.py)
[14/Aug/2024 23:06:00] ERROR [django.request:241] Internal Server Error: /auth/login/
Traceback (most recent call last):
  File "D:\ALL CODES\Professional work\CCS MERCH STORE\merch_store_backend\backend\login\backend.py", line 130, in decrypt
    json_object = json.loads(cleaned_string)
                  ^^^^^^^^^^^^^^^^^^^^^^^^^^
  File "C:\Users\Sakshham\AppData\Local\Programs\Python\Python312\Lib\json\__init__.py", line 346, in loads
    return _default_decoder.decode(s)
           ^^^^^^^^^^^^^^^^^^^^^^^^^^
  File "C:\Users\Sakshham\AppData\Local\Programs\Python\Python312\Lib\json\decoder.py", line 340, in decode
    raise JSONDecodeError("Extra data", s, end)
json.decoder.JSONDecodeError: Extra data: line 1 column 581 (char 580)

During handling of the above exception, another exception occurred:

Traceback (most recent call last):
  File "C:\Users\Sakshham\AppData\Local\Programs\Python\Python312\Lib\site-packages\django\core\handlers\exception.py", line 55, in inner
    response = get_response(request)
               ^^^^^^^^^^^^^^^^^^^^^
  File "C:\Users\Sakshham\AppData\Local\Programs\Python\Python312\Lib\site-packages\django\core\handlers\base.py", line 197, in _get_response
    response = wrapped_callback(request, *callback_args, **callback_kwargs)
               ^^^^^^^^^^^^^^^^^^^^^^^^^^^^^^^^^^^^^^^^^^^^^^^^^^^^^^^^^^^^
  File "C:\Users\Sakshham\AppData\Local\Programs\Python\Python312\Lib\site-packages\django\views\decorators\csrf.py", line 56, in wrapper_view
    return view_func(*args, **kwargs)
           ^^^^^^^^^^^^^^^^^^^^^^^^^^
  File "C:\Users\Sakshham\AppData\Local\Programs\Python\Python312\Lib\site-packages\django\views\generic\base.py", line 104, in view
    return self.dispatch(request, *args, **kwargs)
           ^^^^^^^^^^^^^^^^^^^^^^^^^^^^^^^^^^^^^^^
  File "C:\Users\Sakshham\AppData\Local\Programs\Python\Python312\Lib\site-packages\rest_framework\views.py", line 509, in dispatch
    response = self.handle_exception(exc)
               ^^^^^^^^^^^^^^^^^^^^^^^^^^
  File "C:\Users\Sakshham\AppData\Local\Programs\Python\Python312\Lib\site-packages\rest_framework\views.py", line 469, in handle_exception
    self.raise_uncaught_exception(exc)
  File "C:\Users\Sakshham\AppData\Local\Programs\Python\Python312\Lib\site-packages\rest_framework\views.py", line 480, in raise_uncaught_exception
    raise exc
  File "C:\Users\Sakshham\AppData\Local\Programs\Python\Python312\Lib\site-packages\rest_framework\views.py", line 506, in dispatch
    response = handler(request, *args, **kwargs)
               ^^^^^^^^^^^^^^^^^^^^^^^^^^^^^^^^^
  File "D:\ALL CODES\Professional work\CCS MERCH STORE\merch_store_backend\backend\login\views.py", line 21, in post
    user = authenticate(request, sso_token=sso_token)
           ^^^^^^^^^^^^^^^^^^^^^^^^^^^^^^^^^^^^^^^^^^
  File "C:\Users\Sakshham\AppData\Local\Programs\Python\Python312\Lib\site-packages\django\views\decorators\debug.py", line 42, in sensitive_variables_wrapper
    return func(*func_args, **func_kwargs)
           ^^^^^^^^^^^^^^^^^^^^^^^^^^^^^^^
  File "C:\Users\Sakshham\AppData\Local\Programs\Python\Python312\Lib\site-packages\django\contrib\auth\__init__.py", line 77, in authenticate
    user = backend.authenticate(request, **credentials)
           ^^^^^^^^^^^^^^^^^^^^^^^^^^^^^^^^^^^^^^^^^^^^
  File "D:\ALL CODES\Professional work\CCS MERCH STORE\merch_store_backend\backend\login\backend.py", line 25, in authenticate
    user_info = self.validate_sso_token(sso_token)
                ^^^^^^^^^^^^^^^^^^^^^^^^^^^^^^^^^^
  File "D:\ALL CODES\Professional work\CCS MERCH STORE\merch_store_backend\backend\login\backend.py", line 68, in validate_sso_token
    decrypted_data = decrypt(payload["ex"], jwt_secret)
                     ^^^^^^^^^^^^^^^^^^^^^^^^^^^^^^^^^^
  File "D:\ALL CODES\Professional work\CCS MERCH STORE\merch_store_backend\backend\login\backend.py", line 138, in decrypt
    raise ValueError("Decryption failed or invalid data format")
ValueError: Decryption failed or invalid data format
[14/Aug/2024 23:06:00] ERROR [django.server:212] "POST /auth/login/ HTTP/1.1" 500 162776
[14/Aug/2024 23:16:40] ERROR [django.request:241] Internal Server Error: /auth/login/
Traceback (most recent call last):
  File "D:\ALL CODES\Professional work\CCS MERCH STORE\merch_store_backend\backend\login\backend.py", line 130, in decrypt
    json_object = json.loads(cleaned_string)
                  ^^^^^^^^^^^^^^^^^^^^^^^^^^
  File "C:\Users\Sakshham\AppData\Local\Programs\Python\Python312\Lib\json\__init__.py", line 346, in loads
    return _default_decoder.decode(s)
           ^^^^^^^^^^^^^^^^^^^^^^^^^^
  File "C:\Users\Sakshham\AppData\Local\Programs\Python\Python312\Lib\json\decoder.py", line 340, in decode
    raise JSONDecodeError("Extra data", s, end)
json.decoder.JSONDecodeError: Extra data: line 1 column 581 (char 580)

During handling of the above exception, another exception occurred:

Traceback (most recent call last):
  File "C:\Users\Sakshham\AppData\Local\Programs\Python\Python312\Lib\site-packages\django\core\handlers\exception.py", line 55, in inner
    response = get_response(request)
               ^^^^^^^^^^^^^^^^^^^^^
  File "C:\Users\Sakshham\AppData\Local\Programs\Python\Python312\Lib\site-packages\django\core\handlers\base.py", line 197, in _get_response
    response = wrapped_callback(request, *callback_args, **callback_kwargs)
               ^^^^^^^^^^^^^^^^^^^^^^^^^^^^^^^^^^^^^^^^^^^^^^^^^^^^^^^^^^^^
  File "C:\Users\Sakshham\AppData\Local\Programs\Python\Python312\Lib\site-packages\django\views\decorators\csrf.py", line 56, in wrapper_view
    return view_func(*args, **kwargs)
           ^^^^^^^^^^^^^^^^^^^^^^^^^^
  File "C:\Users\Sakshham\AppData\Local\Programs\Python\Python312\Lib\site-packages\django\views\generic\base.py", line 104, in view
    return self.dispatch(request, *args, **kwargs)
           ^^^^^^^^^^^^^^^^^^^^^^^^^^^^^^^^^^^^^^^
  File "C:\Users\Sakshham\AppData\Local\Programs\Python\Python312\Lib\site-packages\rest_framework\views.py", line 509, in dispatch
    response = self.handle_exception(exc)
               ^^^^^^^^^^^^^^^^^^^^^^^^^^
  File "C:\Users\Sakshham\AppData\Local\Programs\Python\Python312\Lib\site-packages\rest_framework\views.py", line 469, in handle_exception
    self.raise_uncaught_exception(exc)
  File "C:\Users\Sakshham\AppData\Local\Programs\Python\Python312\Lib\site-packages\rest_framework\views.py", line 480, in raise_uncaught_exception
    raise exc
  File "C:\Users\Sakshham\AppData\Local\Programs\Python\Python312\Lib\site-packages\rest_framework\views.py", line 506, in dispatch
    response = handler(request, *args, **kwargs)
               ^^^^^^^^^^^^^^^^^^^^^^^^^^^^^^^^^
  File "D:\ALL CODES\Professional work\CCS MERCH STORE\merch_store_backend\backend\login\views.py", line 21, in post
    user = authenticate(request, sso_token=sso_token)
           ^^^^^^^^^^^^^^^^^^^^^^^^^^^^^^^^^^^^^^^^^^
  File "C:\Users\Sakshham\AppData\Local\Programs\Python\Python312\Lib\site-packages\django\views\decorators\debug.py", line 42, in sensitive_variables_wrapper
    return func(*func_args, **func_kwargs)
           ^^^^^^^^^^^^^^^^^^^^^^^^^^^^^^^
  File "C:\Users\Sakshham\AppData\Local\Programs\Python\Python312\Lib\site-packages\django\contrib\auth\__init__.py", line 77, in authenticate
    user = backend.authenticate(request, **credentials)
           ^^^^^^^^^^^^^^^^^^^^^^^^^^^^^^^^^^^^^^^^^^^^
  File "D:\ALL CODES\Professional work\CCS MERCH STORE\merch_store_backend\backend\login\backend.py", line 25, in authenticate
    user_info = self.validate_sso_token(sso_token)
                ^^^^^^^^^^^^^^^^^^^^^^^^^^^^^^^^^^
  File "D:\ALL CODES\Professional work\CCS MERCH STORE\merch_store_backend\backend\login\backend.py", line 68, in validate_sso_token
    decrypted_data = decrypt(payload["ex"], jwt_secret)
                     ^^^^^^^^^^^^^^^^^^^^^^^^^^^^^^^^^^
  File "D:\ALL CODES\Professional work\CCS MERCH STORE\merch_store_backend\backend\login\backend.py", line 138, in decrypt
    raise ValueError("Decryption failed or invalid data format")
ValueError: Decryption failed or invalid data format
[14/Aug/2024 23:16:40] ERROR [django.server:212] "POST /auth/login/ HTTP/1.1" 500 162776
[14/Aug/2024 23:17:00] ERROR [django.request:241] Internal Server Error: /auth/login/
Traceback (most recent call last):
  File "D:\ALL CODES\Professional work\CCS MERCH STORE\merch_store_backend\backend\login\backend.py", line 130, in decrypt
    json_object = json.loads(cleaned_string)
                  ^^^^^^^^^^^^^^^^^^^^^^^^^^
  File "C:\Users\Sakshham\AppData\Local\Programs\Python\Python312\Lib\json\__init__.py", line 346, in loads
    return _default_decoder.decode(s)
           ^^^^^^^^^^^^^^^^^^^^^^^^^^
  File "C:\Users\Sakshham\AppData\Local\Programs\Python\Python312\Lib\json\decoder.py", line 340, in decode
    raise JSONDecodeError("Extra data", s, end)
json.decoder.JSONDecodeError: Extra data: line 1 column 581 (char 580)

During handling of the above exception, another exception occurred:

Traceback (most recent call last):
  File "C:\Users\Sakshham\AppData\Local\Programs\Python\Python312\Lib\site-packages\django\core\handlers\exception.py", line 55, in inner
    response = get_response(request)
               ^^^^^^^^^^^^^^^^^^^^^
  File "C:\Users\Sakshham\AppData\Local\Programs\Python\Python312\Lib\site-packages\django\core\handlers\base.py", line 197, in _get_response
    response = wrapped_callback(request, *callback_args, **callback_kwargs)
               ^^^^^^^^^^^^^^^^^^^^^^^^^^^^^^^^^^^^^^^^^^^^^^^^^^^^^^^^^^^^
  File "C:\Users\Sakshham\AppData\Local\Programs\Python\Python312\Lib\site-packages\django\views\decorators\csrf.py", line 56, in wrapper_view
    return view_func(*args, **kwargs)
           ^^^^^^^^^^^^^^^^^^^^^^^^^^
  File "C:\Users\Sakshham\AppData\Local\Programs\Python\Python312\Lib\site-packages\django\views\generic\base.py", line 104, in view
    return self.dispatch(request, *args, **kwargs)
           ^^^^^^^^^^^^^^^^^^^^^^^^^^^^^^^^^^^^^^^
  File "C:\Users\Sakshham\AppData\Local\Programs\Python\Python312\Lib\site-packages\rest_framework\views.py", line 509, in dispatch
    response = self.handle_exception(exc)
               ^^^^^^^^^^^^^^^^^^^^^^^^^^
  File "C:\Users\Sakshham\AppData\Local\Programs\Python\Python312\Lib\site-packages\rest_framework\views.py", line 469, in handle_exception
    self.raise_uncaught_exception(exc)
  File "C:\Users\Sakshham\AppData\Local\Programs\Python\Python312\Lib\site-packages\rest_framework\views.py", line 480, in raise_uncaught_exception
    raise exc
  File "C:\Users\Sakshham\AppData\Local\Programs\Python\Python312\Lib\site-packages\rest_framework\views.py", line 506, in dispatch
    response = handler(request, *args, **kwargs)
               ^^^^^^^^^^^^^^^^^^^^^^^^^^^^^^^^^
  File "D:\ALL CODES\Professional work\CCS MERCH STORE\merch_store_backend\backend\login\views.py", line 21, in post
    user = authenticate(request, sso_token=sso_token)
           ^^^^^^^^^^^^^^^^^^^^^^^^^^^^^^^^^^^^^^^^^^
  File "C:\Users\Sakshham\AppData\Local\Programs\Python\Python312\Lib\site-packages\django\views\decorators\debug.py", line 42, in sensitive_variables_wrapper
    return func(*func_args, **func_kwargs)
           ^^^^^^^^^^^^^^^^^^^^^^^^^^^^^^^
  File "C:\Users\Sakshham\AppData\Local\Programs\Python\Python312\Lib\site-packages\django\contrib\auth\__init__.py", line 77, in authenticate
    user = backend.authenticate(request, **credentials)
           ^^^^^^^^^^^^^^^^^^^^^^^^^^^^^^^^^^^^^^^^^^^^
  File "D:\ALL CODES\Professional work\CCS MERCH STORE\merch_store_backend\backend\login\backend.py", line 25, in authenticate
    user_info = self.validate_sso_token(sso_token)
                ^^^^^^^^^^^^^^^^^^^^^^^^^^^^^^^^^^
  File "D:\ALL CODES\Professional work\CCS MERCH STORE\merch_store_backend\backend\login\backend.py", line 68, in validate_sso_token
    decrypted_data = decrypt(payload["ex"], jwt_secret)
                     ^^^^^^^^^^^^^^^^^^^^^^^^^^^^^^^^^^
  File "D:\ALL CODES\Professional work\CCS MERCH STORE\merch_store_backend\backend\login\backend.py", line 138, in decrypt
    raise ValueError("Decryption failed or invalid data format")
ValueError: Decryption failed or invalid data format
[14/Aug/2024 23:17:00] ERROR [django.server:212] "POST /auth/login/ HTTP/1.1" 500 162776
[14/Aug/2024 23:18:10] ERROR [django.request:241] Internal Server Error: /auth/login/
Traceback (most recent call last):
  File "D:\ALL CODES\Professional work\CCS MERCH STORE\merch_store_backend\backend\login\backend.py", line 131, in decrypt
    json_object = json.loads(cleaned_string)
                  ^^^^^^^^^^^^^^^^^^^^^^^^^^
  File "C:\Users\Sakshham\AppData\Local\Programs\Python\Python312\Lib\json\__init__.py", line 346, in loads
    return _default_decoder.decode(s)
           ^^^^^^^^^^^^^^^^^^^^^^^^^^
  File "C:\Users\Sakshham\AppData\Local\Programs\Python\Python312\Lib\json\decoder.py", line 340, in decode
    raise JSONDecodeError("Extra data", s, end)
json.decoder.JSONDecodeError: Extra data: line 1 column 581 (char 580)

During handling of the above exception, another exception occurred:

Traceback (most recent call last):
  File "C:\Users\Sakshham\AppData\Local\Programs\Python\Python312\Lib\site-packages\django\core\handlers\exception.py", line 55, in inner
    response = get_response(request)
               ^^^^^^^^^^^^^^^^^^^^^
  File "C:\Users\Sakshham\AppData\Local\Programs\Python\Python312\Lib\site-packages\django\core\handlers\base.py", line 197, in _get_response
    response = wrapped_callback(request, *callback_args, **callback_kwargs)
               ^^^^^^^^^^^^^^^^^^^^^^^^^^^^^^^^^^^^^^^^^^^^^^^^^^^^^^^^^^^^
  File "C:\Users\Sakshham\AppData\Local\Programs\Python\Python312\Lib\site-packages\django\views\decorators\csrf.py", line 56, in wrapper_view
    return view_func(*args, **kwargs)
           ^^^^^^^^^^^^^^^^^^^^^^^^^^
  File "C:\Users\Sakshham\AppData\Local\Programs\Python\Python312\Lib\site-packages\django\views\generic\base.py", line 104, in view
    return self.dispatch(request, *args, **kwargs)
           ^^^^^^^^^^^^^^^^^^^^^^^^^^^^^^^^^^^^^^^
  File "C:\Users\Sakshham\AppData\Local\Programs\Python\Python312\Lib\site-packages\rest_framework\views.py", line 509, in dispatch
    response = self.handle_exception(exc)
               ^^^^^^^^^^^^^^^^^^^^^^^^^^
  File "C:\Users\Sakshham\AppData\Local\Programs\Python\Python312\Lib\site-packages\rest_framework\views.py", line 469, in handle_exception
    self.raise_uncaught_exception(exc)
  File "C:\Users\Sakshham\AppData\Local\Programs\Python\Python312\Lib\site-packages\rest_framework\views.py", line 480, in raise_uncaught_exception
    raise exc
  File "C:\Users\Sakshham\AppData\Local\Programs\Python\Python312\Lib\site-packages\rest_framework\views.py", line 506, in dispatch
    response = handler(request, *args, **kwargs)
               ^^^^^^^^^^^^^^^^^^^^^^^^^^^^^^^^^
  File "D:\ALL CODES\Professional work\CCS MERCH STORE\merch_store_backend\backend\login\views.py", line 21, in post
    user = authenticate(request, sso_token=sso_token)
           ^^^^^^^^^^^^^^^^^^^^^^^^^^^^^^^^^^^^^^^^^^
  File "C:\Users\Sakshham\AppData\Local\Programs\Python\Python312\Lib\site-packages\django\views\decorators\debug.py", line 42, in sensitive_variables_wrapper
    return func(*func_args, **func_kwargs)
           ^^^^^^^^^^^^^^^^^^^^^^^^^^^^^^^
  File "C:\Users\Sakshham\AppData\Local\Programs\Python\Python312\Lib\site-packages\django\contrib\auth\__init__.py", line 77, in authenticate
    user = backend.authenticate(request, **credentials)
           ^^^^^^^^^^^^^^^^^^^^^^^^^^^^^^^^^^^^^^^^^^^^
  File "D:\ALL CODES\Professional work\CCS MERCH STORE\merch_store_backend\backend\login\backend.py", line 25, in authenticate
    user_info = self.validate_sso_token(sso_token)
                ^^^^^^^^^^^^^^^^^^^^^^^^^^^^^^^^^^
  File "D:\ALL CODES\Professional work\CCS MERCH STORE\merch_store_backend\backend\login\backend.py", line 68, in validate_sso_token
    decrypted_data = decrypt(payload["ex"], jwt_secret)
                     ^^^^^^^^^^^^^^^^^^^^^^^^^^^^^^^^^^
  File "D:\ALL CODES\Professional work\CCS MERCH STORE\merch_store_backend\backend\login\backend.py", line 139, in decrypt
    raise ValueError("Decryption failed or invalid data format")
ValueError: Decryption failed or invalid data format
[14/Aug/2024 23:18:10] ERROR [django.server:212] "POST /auth/login/ HTTP/1.1" 500 162776
[14/Aug/2024 23:47:55] ERROR [django.request:241] Internal Server Error: /auth/login/
Traceback (most recent call last):
  File "D:\ALL CODES\Professional work\CCS MERCH STORE\merch_store_backend\backend\login\backend.py", line 131, in decrypt
    json_object = json.loads(cleaned_string)
                  ^^^^^^^^^^^^^^^^^^^^^^^^^^
  File "C:\Users\Sakshham\AppData\Local\Programs\Python\Python312\Lib\json\__init__.py", line 346, in loads
    return _default_decoder.decode(s)
           ^^^^^^^^^^^^^^^^^^^^^^^^^^
  File "C:\Users\Sakshham\AppData\Local\Programs\Python\Python312\Lib\json\decoder.py", line 340, in decode
    raise JSONDecodeError("Extra data", s, end)
json.decoder.JSONDecodeError: Extra data: line 1 column 581 (char 580)

During handling of the above exception, another exception occurred:

Traceback (most recent call last):
  File "C:\Users\Sakshham\AppData\Local\Programs\Python\Python312\Lib\site-packages\django\core\handlers\exception.py", line 55, in inner
    response = get_response(request)
               ^^^^^^^^^^^^^^^^^^^^^
  File "C:\Users\Sakshham\AppData\Local\Programs\Python\Python312\Lib\site-packages\django\core\handlers\base.py", line 197, in _get_response
    response = wrapped_callback(request, *callback_args, **callback_kwargs)
               ^^^^^^^^^^^^^^^^^^^^^^^^^^^^^^^^^^^^^^^^^^^^^^^^^^^^^^^^^^^^
  File "C:\Users\Sakshham\AppData\Local\Programs\Python\Python312\Lib\site-packages\django\views\decorators\csrf.py", line 56, in wrapper_view
    return view_func(*args, **kwargs)
           ^^^^^^^^^^^^^^^^^^^^^^^^^^
  File "C:\Users\Sakshham\AppData\Local\Programs\Python\Python312\Lib\site-packages\django\views\generic\base.py", line 104, in view
    return self.dispatch(request, *args, **kwargs)
           ^^^^^^^^^^^^^^^^^^^^^^^^^^^^^^^^^^^^^^^
  File "C:\Users\Sakshham\AppData\Local\Programs\Python\Python312\Lib\site-packages\rest_framework\views.py", line 509, in dispatch
    response = self.handle_exception(exc)
               ^^^^^^^^^^^^^^^^^^^^^^^^^^
  File "C:\Users\Sakshham\AppData\Local\Programs\Python\Python312\Lib\site-packages\rest_framework\views.py", line 469, in handle_exception
    self.raise_uncaught_exception(exc)
  File "C:\Users\Sakshham\AppData\Local\Programs\Python\Python312\Lib\site-packages\rest_framework\views.py", line 480, in raise_uncaught_exception
    raise exc
  File "C:\Users\Sakshham\AppData\Local\Programs\Python\Python312\Lib\site-packages\rest_framework\views.py", line 506, in dispatch
    response = handler(request, *args, **kwargs)
               ^^^^^^^^^^^^^^^^^^^^^^^^^^^^^^^^^
  File "D:\ALL CODES\Professional work\CCS MERCH STORE\merch_store_backend\backend\login\views.py", line 21, in post
    user = authenticate(request, sso_token=sso_token)
           ^^^^^^^^^^^^^^^^^^^^^^^^^^^^^^^^^^^^^^^^^^
  File "C:\Users\Sakshham\AppData\Local\Programs\Python\Python312\Lib\site-packages\django\views\decorators\debug.py", line 42, in sensitive_variables_wrapper
    return func(*func_args, **func_kwargs)
           ^^^^^^^^^^^^^^^^^^^^^^^^^^^^^^^
  File "C:\Users\Sakshham\AppData\Local\Programs\Python\Python312\Lib\site-packages\django\contrib\auth\__init__.py", line 77, in authenticate
    user = backend.authenticate(request, **credentials)
           ^^^^^^^^^^^^^^^^^^^^^^^^^^^^^^^^^^^^^^^^^^^^
  File "D:\ALL CODES\Professional work\CCS MERCH STORE\merch_store_backend\backend\login\backend.py", line 25, in authenticate
    user_info = self.validate_sso_token(sso_token)
                ^^^^^^^^^^^^^^^^^^^^^^^^^^^^^^^^^^
  File "D:\ALL CODES\Professional work\CCS MERCH STORE\merch_store_backend\backend\login\backend.py", line 68, in validate_sso_token
    decrypted_data = decrypt(payload["ex"], jwt_secret)
                     ^^^^^^^^^^^^^^^^^^^^^^^^^^^^^^^^^^
  File "D:\ALL CODES\Professional work\CCS MERCH STORE\merch_store_backend\backend\login\backend.py", line 139, in decrypt
    raise ValueError("Decryption failed or invalid data format")
ValueError: Decryption failed or invalid data format
[14/Aug/2024 23:47:55] ERROR [django.server:212] "POST /auth/login/ HTTP/1.1" 500 162776
[14/Aug/2024 23:50:07] ERROR [django.request:241] Internal Server Error: /auth/login/
Traceback (most recent call last):
  File "D:\ALL CODES\Professional work\CCS MERCH STORE\merch_store_backend\backend\login\backend.py", line 131, in decrypt
    json_object = json.loads(decoded_string)
                  ^^^^^^^^^^^^^^^^^^^^^^^^^^
  File "C:\Users\Sakshham\AppData\Local\Programs\Python\Python312\Lib\json\__init__.py", line 346, in loads
    return _default_decoder.decode(s)
           ^^^^^^^^^^^^^^^^^^^^^^^^^^
  File "C:\Users\Sakshham\AppData\Local\Programs\Python\Python312\Lib\json\decoder.py", line 340, in decode
    raise JSONDecodeError("Extra data", s, end)
json.decoder.JSONDecodeError: Extra data: line 1 column 581 (char 580)

During handling of the above exception, another exception occurred:

Traceback (most recent call last):
  File "C:\Users\Sakshham\AppData\Local\Programs\Python\Python312\Lib\site-packages\django\core\handlers\exception.py", line 55, in inner
    response = get_response(request)
               ^^^^^^^^^^^^^^^^^^^^^
  File "C:\Users\Sakshham\AppData\Local\Programs\Python\Python312\Lib\site-packages\django\core\handlers\base.py", line 197, in _get_response
    response = wrapped_callback(request, *callback_args, **callback_kwargs)
               ^^^^^^^^^^^^^^^^^^^^^^^^^^^^^^^^^^^^^^^^^^^^^^^^^^^^^^^^^^^^
  File "C:\Users\Sakshham\AppData\Local\Programs\Python\Python312\Lib\site-packages\django\views\decorators\csrf.py", line 56, in wrapper_view
    return view_func(*args, **kwargs)
           ^^^^^^^^^^^^^^^^^^^^^^^^^^
  File "C:\Users\Sakshham\AppData\Local\Programs\Python\Python312\Lib\site-packages\django\views\generic\base.py", line 104, in view
    return self.dispatch(request, *args, **kwargs)
           ^^^^^^^^^^^^^^^^^^^^^^^^^^^^^^^^^^^^^^^
  File "C:\Users\Sakshham\AppData\Local\Programs\Python\Python312\Lib\site-packages\rest_framework\views.py", line 509, in dispatch
    response = self.handle_exception(exc)
               ^^^^^^^^^^^^^^^^^^^^^^^^^^
  File "C:\Users\Sakshham\AppData\Local\Programs\Python\Python312\Lib\site-packages\rest_framework\views.py", line 469, in handle_exception
    self.raise_uncaught_exception(exc)
  File "C:\Users\Sakshham\AppData\Local\Programs\Python\Python312\Lib\site-packages\rest_framework\views.py", line 480, in raise_uncaught_exception
    raise exc
  File "C:\Users\Sakshham\AppData\Local\Programs\Python\Python312\Lib\site-packages\rest_framework\views.py", line 506, in dispatch
    response = handler(request, *args, **kwargs)
               ^^^^^^^^^^^^^^^^^^^^^^^^^^^^^^^^^
  File "D:\ALL CODES\Professional work\CCS MERCH STORE\merch_store_backend\backend\login\views.py", line 21, in post
    user = authenticate(request, sso_token=sso_token)
           ^^^^^^^^^^^^^^^^^^^^^^^^^^^^^^^^^^^^^^^^^^
  File "C:\Users\Sakshham\AppData\Local\Programs\Python\Python312\Lib\site-packages\django\views\decorators\debug.py", line 42, in sensitive_variables_wrapper
    return func(*func_args, **func_kwargs)
           ^^^^^^^^^^^^^^^^^^^^^^^^^^^^^^^
  File "C:\Users\Sakshham\AppData\Local\Programs\Python\Python312\Lib\site-packages\django\contrib\auth\__init__.py", line 77, in authenticate
    user = backend.authenticate(request, **credentials)
           ^^^^^^^^^^^^^^^^^^^^^^^^^^^^^^^^^^^^^^^^^^^^
  File "D:\ALL CODES\Professional work\CCS MERCH STORE\merch_store_backend\backend\login\backend.py", line 25, in authenticate
    user_info = self.validate_sso_token(sso_token)
                ^^^^^^^^^^^^^^^^^^^^^^^^^^^^^^^^^^
  File "D:\ALL CODES\Professional work\CCS MERCH STORE\merch_store_backend\backend\login\backend.py", line 68, in validate_sso_token
    decrypted_data = decrypt(payload["ex"], jwt_secret)
                     ^^^^^^^^^^^^^^^^^^^^^^^^^^^^^^^^^^
  File "D:\ALL CODES\Professional work\CCS MERCH STORE\merch_store_backend\backend\login\backend.py", line 139, in decrypt
    raise ValueError("Decryption failed or invalid data format")
ValueError: Decryption failed or invalid data format
[14/Aug/2024 23:50:07] ERROR [django.server:212] "POST /auth/login/ HTTP/1.1" 500 160014
[15/Aug/2024 00:02:52] ERROR [django.request:241] Internal Server Error: /auth/login/
Traceback (most recent call last):
  File "C:\Users\Sakshham\AppData\Local\Programs\Python\Python312\Lib\site-packages\django\core\handlers\exception.py", line 55, in inner
    response = get_response(request)
               ^^^^^^^^^^^^^^^^^^^^^
  File "C:\Users\Sakshham\AppData\Local\Programs\Python\Python312\Lib\site-packages\django\core\handlers\base.py", line 197, in _get_response
    response = wrapped_callback(request, *callback_args, **callback_kwargs)
               ^^^^^^^^^^^^^^^^^^^^^^^^^^^^^^^^^^^^^^^^^^^^^^^^^^^^^^^^^^^^
  File "C:\Users\Sakshham\AppData\Local\Programs\Python\Python312\Lib\site-packages\django\views\decorators\csrf.py", line 56, in wrapper_view
    return view_func(*args, **kwargs)
           ^^^^^^^^^^^^^^^^^^^^^^^^^^
  File "C:\Users\Sakshham\AppData\Local\Programs\Python\Python312\Lib\site-packages\django\views\generic\base.py", line 104, in view
    return self.dispatch(request, *args, **kwargs)
           ^^^^^^^^^^^^^^^^^^^^^^^^^^^^^^^^^^^^^^^
  File "C:\Users\Sakshham\AppData\Local\Programs\Python\Python312\Lib\site-packages\rest_framework\views.py", line 509, in dispatch
    response = self.handle_exception(exc)
               ^^^^^^^^^^^^^^^^^^^^^^^^^^
  File "C:\Users\Sakshham\AppData\Local\Programs\Python\Python312\Lib\site-packages\rest_framework\views.py", line 469, in handle_exception
    self.raise_uncaught_exception(exc)
  File "C:\Users\Sakshham\AppData\Local\Programs\Python\Python312\Lib\site-packages\rest_framework\views.py", line 480, in raise_uncaught_exception
    raise exc
  File "C:\Users\Sakshham\AppData\Local\Programs\Python\Python312\Lib\site-packages\rest_framework\views.py", line 506, in dispatch
    response = handler(request, *args, **kwargs)
               ^^^^^^^^^^^^^^^^^^^^^^^^^^^^^^^^^
  File "D:\ALL CODES\Professional work\CCS MERCH STORE\merch_store_backend\backend\login\views.py", line 21, in post
    user = authenticate(request, sso_token=sso_token)
           ^^^^^^^^^^^^^^^^^^^^^^^^^^^^^^^^^^^^^^^^^^
  File "C:\Users\Sakshham\AppData\Local\Programs\Python\Python312\Lib\site-packages\django\views\decorators\debug.py", line 42, in sensitive_variables_wrapper
    return func(*func_args, **func_kwargs)
           ^^^^^^^^^^^^^^^^^^^^^^^^^^^^^^^
  File "C:\Users\Sakshham\AppData\Local\Programs\Python\Python312\Lib\site-packages\django\contrib\auth\__init__.py", line 77, in authenticate
    user = backend.authenticate(request, **credentials)
           ^^^^^^^^^^^^^^^^^^^^^^^^^^^^^^^^^^^^^^^^^^^^
  File "D:\ALL CODES\Professional work\CCS MERCH STORE\merch_store_backend\backend\login\backend.py", line 26, in authenticate
    user_info = self.validate_sso_token(sso_token)
                ^^^^^^^^^^^^^^^^^^^^^^^^^^^^^^^^^^
  File "D:\ALL CODES\Professional work\CCS MERCH STORE\merch_store_backend\backend\login\backend.py", line 69, in validate_sso_token
    decrypted_data = decrypt(payload["ex"], jwt_secret)
                             ~~~~~~~^^^^^^
KeyError: 'ex'
[15/Aug/2024 00:02:52] ERROR [django.server:212] "POST /auth/login/ HTTP/1.1" 500 120742
[15/Aug/2024 00:03:03] ERROR [django.request:241] Internal Server Error: /auth/login/
Traceback (most recent call last):
  File "D:\ALL CODES\Professional work\CCS MERCH STORE\merch_store_backend\backend\login\backend.py", line 30, in authenticate
    user = User.objects.get(email=user_info["email"])
           ^^^^^^^^^^^^^^^^^^^^^^^^^^^^^^^^^^^^^^^^^^
  File "C:\Users\Sakshham\AppData\Local\Programs\Python\Python312\Lib\site-packages\django\db\models\manager.py", line 87, in manager_method
    return getattr(self.get_queryset(), name)(*args, **kwargs)
           ^^^^^^^^^^^^^^^^^^^^^^^^^^^^^^^^^^^^^^^^^^^^^^^^^^^
  File "C:\Users\Sakshham\AppData\Local\Programs\Python\Python312\Lib\site-packages\django\db\models\query.py", line 637, in get
    raise self.model.DoesNotExist(
login.models.CustomUser.DoesNotExist: CustomUser matching query does not exist.

During handling of the above exception, another exception occurred:

Traceback (most recent call last):
  File "C:\Users\Sakshham\AppData\Local\Programs\Python\Python312\Lib\site-packages\django\db\backends\utils.py", line 89, in _execute
    return self.cursor.execute(sql, params)
           ^^^^^^^^^^^^^^^^^^^^^^^^^^^^^^^^
psycopg2.errors.UniqueViolation: duplicate key value violates unique constraint "login_customuser_pkey"
DETAIL:  Key (id)=(102303094) already exists.


The above exception was the direct cause of the following exception:

Traceback (most recent call last):
  File "C:\Users\Sakshham\AppData\Local\Programs\Python\Python312\Lib\site-packages\django\core\handlers\exception.py", line 55, in inner
    response = get_response(request)
               ^^^^^^^^^^^^^^^^^^^^^
  File "C:\Users\Sakshham\AppData\Local\Programs\Python\Python312\Lib\site-packages\django\core\handlers\base.py", line 197, in _get_response
    response = wrapped_callback(request, *callback_args, **callback_kwargs)
               ^^^^^^^^^^^^^^^^^^^^^^^^^^^^^^^^^^^^^^^^^^^^^^^^^^^^^^^^^^^^
  File "C:\Users\Sakshham\AppData\Local\Programs\Python\Python312\Lib\site-packages\django\views\decorators\csrf.py", line 56, in wrapper_view
    return view_func(*args, **kwargs)
           ^^^^^^^^^^^^^^^^^^^^^^^^^^
  File "C:\Users\Sakshham\AppData\Local\Programs\Python\Python312\Lib\site-packages\django\views\generic\base.py", line 104, in view
    return self.dispatch(request, *args, **kwargs)
           ^^^^^^^^^^^^^^^^^^^^^^^^^^^^^^^^^^^^^^^
  File "C:\Users\Sakshham\AppData\Local\Programs\Python\Python312\Lib\site-packages\rest_framework\views.py", line 509, in dispatch
    response = self.handle_exception(exc)
               ^^^^^^^^^^^^^^^^^^^^^^^^^^
  File "C:\Users\Sakshham\AppData\Local\Programs\Python\Python312\Lib\site-packages\rest_framework\views.py", line 469, in handle_exception
    self.raise_uncaught_exception(exc)
  File "C:\Users\Sakshham\AppData\Local\Programs\Python\Python312\Lib\site-packages\rest_framework\views.py", line 480, in raise_uncaught_exception
    raise exc
  File "C:\Users\Sakshham\AppData\Local\Programs\Python\Python312\Lib\site-packages\rest_framework\views.py", line 506, in dispatch
    response = handler(request, *args, **kwargs)
               ^^^^^^^^^^^^^^^^^^^^^^^^^^^^^^^^^
  File "D:\ALL CODES\Professional work\CCS MERCH STORE\merch_store_backend\backend\login\views.py", line 21, in post
    user = authenticate(request, sso_token=sso_token)
           ^^^^^^^^^^^^^^^^^^^^^^^^^^^^^^^^^^^^^^^^^^
  File "C:\Users\Sakshham\AppData\Local\Programs\Python\Python312\Lib\site-packages\django\views\decorators\debug.py", line 42, in sensitive_variables_wrapper
    return func(*func_args, **func_kwargs)
           ^^^^^^^^^^^^^^^^^^^^^^^^^^^^^^^
  File "C:\Users\Sakshham\AppData\Local\Programs\Python\Python312\Lib\site-packages\django\contrib\auth\__init__.py", line 77, in authenticate
    user = backend.authenticate(request, **credentials)
           ^^^^^^^^^^^^^^^^^^^^^^^^^^^^^^^^^^^^^^^^^^^^
  File "D:\ALL CODES\Professional work\CCS MERCH STORE\merch_store_backend\backend\login\backend.py", line 42, in authenticate
    user = User.objects.create(
           ^^^^^^^^^^^^^^^^^^^^
  File "C:\Users\Sakshham\AppData\Local\Programs\Python\Python312\Lib\site-packages\django\db\models\manager.py", line 87, in manager_method
    return getattr(self.get_queryset(), name)(*args, **kwargs)
           ^^^^^^^^^^^^^^^^^^^^^^^^^^^^^^^^^^^^^^^^^^^^^^^^^^^
  File "C:\Users\Sakshham\AppData\Local\Programs\Python\Python312\Lib\site-packages\django\db\models\query.py", line 658, in create
    obj.save(force_insert=True, using=self.db)
  File "C:\Users\Sakshham\AppData\Local\Programs\Python\Python312\Lib\site-packages\django\contrib\auth\base_user.py", line 76, in save
    super().save(*args, **kwargs)
  File "C:\Users\Sakshham\AppData\Local\Programs\Python\Python312\Lib\site-packages\django\db\models\base.py", line 814, in save
    self.save_base(
  File "C:\Users\Sakshham\AppData\Local\Programs\Python\Python312\Lib\site-packages\django\db\models\base.py", line 877, in save_base
    updated = self._save_table(
              ^^^^^^^^^^^^^^^^^
  File "C:\Users\Sakshham\AppData\Local\Programs\Python\Python312\Lib\site-packages\django\db\models\base.py", line 1020, in _save_table
    results = self._do_insert(
              ^^^^^^^^^^^^^^^^
  File "C:\Users\Sakshham\AppData\Local\Programs\Python\Python312\Lib\site-packages\django\db\models\base.py", line 1061, in _do_insert
    return manager._insert(
           ^^^^^^^^^^^^^^^^
  File "C:\Users\Sakshham\AppData\Local\Programs\Python\Python312\Lib\site-packages\django\db\models\manager.py", line 87, in manager_method
    return getattr(self.get_queryset(), name)(*args, **kwargs)
           ^^^^^^^^^^^^^^^^^^^^^^^^^^^^^^^^^^^^^^^^^^^^^^^^^^^
  File "C:\Users\Sakshham\AppData\Local\Programs\Python\Python312\Lib\site-packages\django\db\models\query.py", line 1805, in _insert
    return query.get_compiler(using=using).execute_sql(returning_fields)
           ^^^^^^^^^^^^^^^^^^^^^^^^^^^^^^^^^^^^^^^^^^^^^^^^^^^^^^^^^^^^^
  File "C:\Users\Sakshham\AppData\Local\Programs\Python\Python312\Lib\site-packages\django\db\models\sql\compiler.py", line 1822, in execute_sql
    cursor.execute(sql, params)
  File "C:\Users\Sakshham\AppData\Local\Programs\Python\Python312\Lib\site-packages\django\db\backends\utils.py", line 102, in execute
    return super().execute(sql, params)
           ^^^^^^^^^^^^^^^^^^^^^^^^^^^^
  File "C:\Users\Sakshham\AppData\Local\Programs\Python\Python312\Lib\site-packages\django\db\backends\utils.py", line 67, in execute
    return self._execute_with_wrappers(
           ^^^^^^^^^^^^^^^^^^^^^^^^^^^^
  File "C:\Users\Sakshham\AppData\Local\Programs\Python\Python312\Lib\site-packages\django\db\backends\utils.py", line 80, in _execute_with_wrappers
    return executor(sql, params, many, context)
           ^^^^^^^^^^^^^^^^^^^^^^^^^^^^^^^^^^^^
  File "C:\Users\Sakshham\AppData\Local\Programs\Python\Python312\Lib\site-packages\django\db\backends\utils.py", line 84, in _execute
    with self.db.wrap_database_errors:
  File "C:\Users\Sakshham\AppData\Local\Programs\Python\Python312\Lib\site-packages\django\db\utils.py", line 91, in __exit__
    raise dj_exc_value.with_traceback(traceback) from exc_value
  File "C:\Users\Sakshham\AppData\Local\Programs\Python\Python312\Lib\site-packages\django\db\backends\utils.py", line 89, in _execute
    return self.cursor.execute(sql, params)
           ^^^^^^^^^^^^^^^^^^^^^^^^^^^^^^^^
django.db.utils.IntegrityError: duplicate key value violates unique constraint "login_customuser_pkey"
DETAIL:  Key (id)=(102303094) already exists.

[15/Aug/2024 00:03:03] ERROR [django.server:212] "POST /auth/login/ HTTP/1.1" 500 227160
